Workbook

Sheet Info
A1: Subject
A2: Syllabus | D2: <- ALWAYS FILL THIS OUT
A3: Grade
A4: Student Name
A5: Student Surname | D5: Marksheet tool v1.2.3
A6: EM Requested
A7: Date Completed
B42: v1.0ss1

Sheet Input Sheet
A2: Question number | B2: Section/ Taxonomy Title | C2: Marks Scored | D2: Marks Available | E2: Select Error Type | F2: Marks Lost | G2: INSTRUCTIONS
A3: 1.a. | B3: Number Patterns | C3: 2 | D3: 2 | E3: No error | F3: =IF(D3-C3=0,"",D3-C3) | G3: 1. | H3: Fill these out at your lesuire | K3: 90%-100%
A4: 1.b. | B4: Number Patterns | C4: 1 | D4: 2 | E4: Application | F4: =IF(D4-C4=0,"",D4-C4) -> 1 | G4: 2. | H4: Question Number and Section/ Tax Title are text. So can do "4.3a" in Q number | K4: 75%-89%
A5: 2. | B5: Number Patterns | C5: 0 | D5: 5 | E5: Concept | F5: =IF(D5-C5=0,"",D5-C5) -> 5 | G5: 3. | H5: Marks Scored and Marks available must be numbers, can have decimals | K5: 60%-74%
A6: 3.a. | B6: Exponents | C6: 0 | D6: 3 | E6: Careless | F6: =IF(D6-C6=0,"",D6-C6) -> 3 | G6: 4. | H6: Ensure correct spelling of Section/ Tax Title (or you will have duplicates on next page) | K6: 40%-59%
A7: 3.b. | B7: Exponents | C7: 0 | D7: 4 | E7: Misread Direction | F7: =IF(D7-C7=0,"",D7-C7) -> 4 | G7: 5. | H7: Do not edit Marks Lost column. The calculation is atuomatic | K7: 25%-39%
A8: 4. | B8: Algebraic Expressions | C8: 0 | D8: 4 | E8: Application | F8: =IF(D8-C8=0,"",D8-C8) -> 4 | G8: 6. | H8: When complete, head over to next tab for analysis | K8: 1%-24%
B9: Number Patterns | C9: 2 | D9: 2 | E9: No error | F9: =IF(D9-C9=0,"",D9-C9) | G9: 7. | H9: On next page change colours of "Performance in each section" graph. According to --> | K9: 0%
B10: Number Patterns | C10: 1 | D10: 2 | E10: Application | F10: =IF(D10-C10=0,"",D10-C10) -> 1 | G10: 8. | H10: Leave the Pie Chart to have different colours for each section
B11: Number Patterns | C11: 0 | D11: 5 | E11: Concept | F11: =IF(D11-C11=0,"",D11-C11) -> 5
B12: Exponents | C12: 0 | D12: 3 | E12: Careless | F12: =IF(D12-C12=0,"",D12-C12) -> 3 | H12: <- This sheet works for Sections and Tax. Breakdowns
B13: Exponents | C13: 0 | D13: 4 | E13: Misread Direction | F13: =IF(D13-C13=0,"",D13-C13) -> 4
B14: Algebraic Expressions | C14: 0 | D14: 4 | E14: Application | F14: =IF(D14-C14=0,"",D14-C14) -> 4
B15: Functions | C15: 6 | D15: 8 | E15: Concept | F15: =IF(D15-C15=0,"",D15-C15) -> 2
B16: Trigonometry | C16: 4 | D16: 5 | E16: Test Procedure | F16: =IF(D16-C16=0,"",D16-C16) -> 1
B17: Exponents | C17: 0 | D17: 1 | E17: Test Procedure | F17: =IF(D17-C17=0,"",D17-C17) -> 1
B18: Exponents | C18: 0 | D18: 1 | E18: Omission | F18: =IF(D18-C18=0,"",D18-C18) -> 1
F19: =IF(D19-C19=0,"",D19-C19)
F20: =IF(D20-C20=0,"",D20-C20)
F21: =IF(D21-C21=0,"",D21-C21)
F22: =IF(D22-C22=0,"",D22-C22)
F23: =IF(D23-C23=0,"",D23-C23)
F24: =IF(D24-C24=0,"",D24-C24)
F25: =IF(D25-C25=0,"",D25-C25)
F26: =IF(D26-C26=0,"",D26-C26)
F27: =IF(D27-C27=0,"",D27-C27)
F28: =IF(D28-C28=0,"",D28-C28)
F29: =IF(D29-C29=0,"",D29-C29)
F30: =IF(D30-C30=0,"",D30-C30)
... F1001: =IF(D1001-C1001=0,"",D1001-C1001)

Sheet Calculation
L1: Error Type Sum | M1: =(IF(SUM(M6:M1005)=0,RAND()/1000,SUM(M6:M1005)+(RAND()/1000))) -> 8.0004544 | N1: =(IF(SUM(N6:N1005)=0,RAND()/1000,SUM(N6:N1005)+(RAND()/1000))) -> 6.0009209 | O1: =(IF(SUM(O6:O1005)=0,RAND()/1000,SUM(O6:O1005)+(RAND()/1000))) -> 12.000695 | P1: =(IF(SUM(P6:P1005)=0,RAND()/1000,SUM(P6:P1005)+(RAND()/1000))) -> 10.000351 | Q1: =(IF(SUM(Q6:Q1005)=0,RAND()/1000,SUM(Q6:Q1005)+(RAND()/1000))) -> 2.0009449 | R1: =(IF(SUM(R6:R1005)=0,RAND()/1000,SUM(R6:R1005)+(RAND()/1000))) -> 1.0009233 | S1: =(IF(SUM(S6:S1005)=0,RAND()/1000,SUM(S6:S1005)+(RAND()/1000))) -> 0.00035197042
L2: Error Type Rank | M2: =IFERROR(RANK(M1,$M$1:$R$1,0),"") -> 3 | N2: =IFERROR(RANK(N1,$M$1:$R$1,0),"") -> 4 | O2: =IFERROR(RANK(O1,$M$1:$R$1,0),"") -> 1 | P2: =IFERROR(RANK(P1,$M$1:$R$1,0),"") -> 2 | Q2: =IFERROR(RANK(Q1,$M$1:$R$1,0),"") -> 5 | R2: =IFERROR(RANK(R1,$M$1:$R$1,0),"") -> 6 | S2: =IFERROR(RANK(S1,$M$1:$R$1,0),"")
M3: 1 | N3: 2 | O3: 3 | P3: 4 | Q3: 5 | R3: 6
A4: Name | B4: Flag | C4: Marks | D4: Out Of | E4: Percentage Rank | F4: Marks Lost Rank | G4: Error Type Rank | H4: =MAX(E6:E1004) -> 5 | K4: Perc | L4: Marks Lost | M4: Misread Direction | N4: Careless | O4: Concept | P4: Application | Q4: Test Procedure | R4: Omission | S4: No Error | U4: Error Type List for drop down list
M5: 1 | N5: 2 | O5: 3 | P5: 4 | Q5: 5 | R5: 6
A6: =IF('Input Sheet'!B3=0,"",'Input Sheet'!B3) -> Number Patterns | B6: =IFERROR(VLOOKUP(A6,$A7:A$1005,1,FALSE)=0,1) -> FALSE | C6: =SUMIF('Input Sheet'!B$3:B$1000,A6,'Input Sheet'!C$3:C$1000) -> 6 | D6: =SUMIF('Input Sheet'!B$3:B$1000,A6,'Input Sheet'!D$3:D$1000) -> 18 | E6: =IFERROR(RANK(K6,K$6:K$1004,1),"") | F6: =IFERROR(RANK(L6,L$6:L$1004,1),"") | G6: =IFERROR(RANK(L6,L$6:L$1004,0),"") | H6: =IF($B6=1,$A6,"") | I6: =IF($B6=1,$C6,"") | J6: =IF($B6=1,$D6,"") | K6: =IF($B6=1,$C6/$D6+RAND()/1000,"") | L6: =IF($B6=1,$D6-$C6+RAND()/1000,"") | M6: =IF(SUMIFS('Input Sheet'!$F$3:$F$1001,'Input Sheet'!$B$3:$B$1001,$H6,'Input Sheet'!$E$3:$E$1001,M$4)=0,"",SUMIFS('Input Sheet'!$F$3:$F$1001,'Input Sheet'!$B$3:$B$1001,$H6,'Input Sheet'!$E$3:$E$1001,M$4)) | N6: =IF(SUMIFS('Input Sheet'!$F$3:$F$1001,'Input Sheet'!$B$3:$B$1001,$H6,'Input Sheet'!$E$3:$E$1001,N$4)=0,"",SUMIFS('Input Sheet'!$F$3:$F$1001,'Input Sheet'!$B$3:$B$1001,$H6,'Input Sheet'!$E$3:$E$1001,N$4)) | O6: =IF(SUMIFS('Input Sheet'!$F$3:$F$1001,'Input Sheet'!$B$3:$B$1001,$H6,'Input Sheet'!$E$3:$E$1001,O$4)=0,"",SUMIFS('Input Sheet'!$F$3:$F$1001,'Input Sheet'!$B$3:$B$1001,$H6,'Input Sheet'!$E$3:$E$1001,O$4)) | P6: =IF(SUMIFS('Input Sheet'!$F$3:$F$1001,'Input Sheet'!$B$3:$B$1001,$H6,'Input Sheet'!$E$3:$E$1001,P$4)=0,"",SUMIFS('Input Sheet'!$F$3:$F$1001,'Input Sheet'!$B$3:$B$1001,$H6,'Input Sheet'!$E$3:$E$1001,P$4)) | Q6: =IF(SUMIFS('Input Sheet'!$F$3:$F$1001,'Input Sheet'!$B$3:$B$1001,$H6,'Input Sheet'!$E$3:$E$1001,Q$4)=0,"",SUMIFS('Input Sheet'!$F$3:$F$1001,'Input Sheet'!$B$3:$B$1001,$H6,'Input Sheet'!$E$3:$E$1001,Q$4)) | R6: =IF(SUMIFS('Input Sheet'!$F$3:$F$1001,'Input Sheet'!$B$3:$B$1001,$H6,'Input Sheet'!$E$3:$E$1001,R$4)=0,"",SUMIFS('Input Sheet'!$F$3:$F$1001,'Input Sheet'!$B$3:$B$1001,$H6,'Input Sheet'!$E$3:$E$1001,R$4)) | S6: =IF(SUMIFS('Input Sheet'!$F$3:$F$1001,'Input Sheet'!$B$3:$B$1001,$H6,'Input Sheet'!$E$3:$E$1001,S$4)=0,"",SUMIFS('Input Sheet'!$F$3:$F$1001,'Input Sheet'!$B$3:$B$1001,$H6,'Input Sheet'!$E$3:$E$1001,S$4)) | T6: 1 | U6: Misread Direction | V6: =SUM(M6:M1005) -> 8
A7: =IF('Input Sheet'!B4=0,"",'Input Sheet'!B4) -> Number Patterns | B7: =IFERROR(VLOOKUP(A7,$A8:A$1005,1,FALSE)=0,1) -> FALSE | C7: =SUMIF('Input Sheet'!B$3:B$1000,A7,'Input Sheet'!C$3:C$1000) -> 6 | D7: =SUMIF('Input Sheet'!B$3:B$1000,A7,'Input Sheet'!D$3:D$1000) -> 18 | E7: =IFERROR(RANK(K7,K$6:K$1004,1),"") | F7: =IFERROR(RANK(L7,L$6:L$1004,1),"") | G7: =IFERROR(RANK(L7,L$6:L$1004,0),"") | H7: =IF($B7=1,$A7,"") | I7: =IF($B7=1,$C7,"") | J7: =IF($B7=1,$D7,"") | K7: =IF($B7=1,$C7/$D7+RAND()/1000,"") | L7: =IF($B7=1,$D7-$C7+RAND()/1000,"") | M7: =IF(SUMIFS('Input Sheet'!$F$3:$F$1001,'Input Sheet'!$B$3:$B$1001,$H7,'Input Sheet'!$E$3:$E$1001,M$4)=0,"",SUMIFS('Input Sheet'!$F$3:$F$1001,'Input Sheet'!$B$3:$B$1001,$H7,'Input Sheet'!$E$3:$E$1001,M$4)) | N7: =IF(SUMIFS('Input Sheet'!$F$3:$F$1001,'Input Sheet'!$B$3:$B$1001,$H7,'Input Sheet'!$E$3:$E$1001,N$4)=0,"",SUMIFS('Input Sheet'!$F$3:$F$1001,'Input Sheet'!$B$3:$B$1001,$H7,'Input Sheet'!$E$3:$E$1001,N$4)) | O7: =IF(SUMIFS('Input Sheet'!$F$3:$F$1001,'Input Sheet'!$B$3:$B$1001,$H7,'Input Sheet'!$E$3:$E$1001,O$4)=0,"",SUMIFS('Input Sheet'!$F$3:$F$1001,'Input Sheet'!$B$3:$B$1001,$H7,'Input Sheet'!$E$3:$E$1001,O$4)) | P7: =IF(SUMIFS('Input Sheet'!$F$3:$F$1001,'Input Sheet'!$B$3:$B$1001,$H7,'Input Sheet'!$E$3:$E$1001,P$4)=0,"",SUMIFS('Input Sheet'!$F$3:$F$1001,'Input Sheet'!$B$3:$B$1001,$H7,'Input Sheet'!$E$3:$E$1001,P$4)) | Q7: =IF(SUMIFS('Input Sheet'!$F$3:$F$1001,'Input Sheet'!$B$3:$B$1001,$H7,'Input Sheet'!$E$3:$E$1001,Q$4)=0,"",SUMIFS('Input Sheet'!$F$3:$F$1001,'Input Sheet'!$B$3:$B$1001,$H7,'Input Sheet'!$E$3:$E$1001,Q$4)) | R7: =IF(SUMIFS('Input Sheet'!$F$3:$F$1001,'Input Sheet'!$B$3:$B$1001,$H7,'Input Sheet'!$E$3:$E$1001,R$4)=0,"",SUMIFS('Input Sheet'!$F$3:$F$1001,'Input Sheet'!$B$3:$B$1001,$H7,'Input Sheet'!$E$3:$E$1001,R$4)) | S7: =IF(SUMIFS('Input Sheet'!$F$3:$F$1001,'Input Sheet'!$B$3:$B$1001,$H7,'Input Sheet'!$E$3:$E$1001,S$4)=0,"",SUMIFS('Input Sheet'!$F$3:$F$1001,'Input Sheet'!$B$3:$B$1001,$H7,'Input Sheet'!$E$3:$E$1001,S$4)) | T7: 2 | U7: Careless | V7: =SUM(N6:N1005) -> 6
A8: =IF('Input Sheet'!B5=0,"",'Input Sheet'!B5) -> Number Patterns | B8: =IFERROR(VLOOKUP(A8,$A9:A$1005,1,FALSE)=0,1) -> FALSE | C8: =SUMIF('Input Sheet'!B$3:B$1000,A8,'Input Sheet'!C$3:C$1000) -> 6 | D8: =SUMIF('Input Sheet'!B$3:B$1000,A8,'Input Sheet'!D$3:D$1000) -> 18 | E8: =IFERROR(RANK(K8,K$6:K$1004,1),"") | F8: =IFERROR(RANK(L8,L$6:L$1004,1),"") | G8: =IFERROR(RANK(L8,L$6:L$1004,0),"") | H8: =IF($B8=1,$A8,"") | I8: =IF($B8=1,$C8,"") | J8: =IF($B8=1,$D8,"") | K8: =IF($B8=1,$C8/$D8+RAND()/1000,"") | L8: =IF($B8=1,$D8-$C8+RAND()/1000,"") | M8: =IF(SUMIFS('Input Sheet'!$F$3:$F$1001,'Input Sheet'!$B$3:$B$1001,$H8,'Input Sheet'!$E$3:$E$1001,M$4)=0,"",SUMIFS('Input Sheet'!$F$3:$F$1001,'Input Sheet'!$B$3:$B$1001,$H8,'Input Sheet'!$E$3:$E$1001,M$4)) | N8: =IF(SUMIFS('Input Sheet'!$F$3:$F$1001,'Input Sheet'!$B$3:$B$1001,$H8,'Input Sheet'!$E$3:$E$1001,N$4)=0,"",SUMIFS('Input Sheet'!$F$3:$F$1001,'Input Sheet'!$B$3:$B$1001,$H8,'Input Sheet'!$E$3:$E$1001,N$4)) | O8: =IF(SUMIFS('Input Sheet'!$F$3:$F$1001,'Input Sheet'!$B$3:$B$1001,$H8,'Input Sheet'!$E$3:$E$1001,O$4)=0,"",SUMIFS('Input Sheet'!$F$3:$F$1001,'Input Sheet'!$B$3:$B$1001,$H8,'Input Sheet'!$E$3:$E$1001,O$4)) | P8: =IF(SUMIFS('Input Sheet'!$F$3:$F$1001,'Input Sheet'!$B$3:$B$1001,$H8,'Input Sheet'!$E$3:$E$1001,P$4)=0,"",SUMIFS('Input Sheet'!$F$3:$F$1001,'Input Sheet'!$B$3:$B$1001,$H8,'Input Sheet'!$E$3:$E$1001,P$4)) | Q8: =IF(SUMIFS('Input Sheet'!$F$3:$F$1001,'Input Sheet'!$B$3:$B$1001,$H8,'Input Sheet'!$E$3:$E$1001,Q$4)=0,"",SUMIFS('Input Sheet'!$F$3:$F$1001,'Input Sheet'!$B$3:$B$1001,$H8,'Input Sheet'!$E$3:$E$1001,Q$4)) | R8: =IF(SUMIFS('Input Sheet'!$F$3:$F$1001,'Input Sheet'!$B$3:$B$1001,$H8,'Input Sheet'!$E$3:$E$1001,R$4)=0,"",SUMIFS('Input Sheet'!$F$3:$F$1001,'Input Sheet'!$B$3:$B$1001,$H8,'Input Sheet'!$E$3:$E$1001,R$4)) | S8: =IF(SUMIFS('Input Sheet'!$F$3:$F$1001,'Input Sheet'!$B$3:$B$1001,$H8,'Input Sheet'!$E$3:$E$1001,S$4)=0,"",SUMIFS('Input Sheet'!$F$3:$F$1001,'Input Sheet'!$B$3:$B$1001,$H8,'Input Sheet'!$E$3:$E$1001,S$4)) | T8: 3 | U8: Concept | V8: =SUM(O6:O1005) -> 12
A9: =IF('Input Sheet'!B6=0,"",'Input Sheet'!B6) -> Exponents | B9: =IFERROR(VLOOKUP(A9,$A10:A$1005,1,FALSE)=0,1) -> FALSE | C9: =SUMIF('Input Sheet'!B$3:B$1000,A9,'Input Sheet'!C$3:C$1000) -> 0 | D9: =SUMIF('Input Sheet'!B$3:B$1000,A9,'Input Sheet'!D$3:D$1000) -> 16 | E9: =IFERROR(RANK(K9,K$6:K$1004,1),"") | F9: =IFERROR(RANK(L9,L$6:L$1004,1),"") | G9: =IFERROR(RANK(L9,L$6:L$1004,0),"") | H9: =IF($B9=1,$A9,"") | I9: =IF($B9=1,$C9,"") | J9: =IF($B9=1,$D9,"") | K9: =IF($B9=1,$C9/$D9+RAND()/1000,"") | L9: =IF($B9=1,$D9-$C9+RAND()/1000,"") | M9: =IF(SUMIFS('Input Sheet'!$F$3:$F$1001,'Input Sheet'!$B$3:$B$1001,$H9,'Input Sheet'!$E$3:$E$1001,M$4)=0,"",SUMIFS('Input Sheet'!$F$3:$F$1001,'Input Sheet'!$B$3:$B$1001,$H9,'Input Sheet'!$E$3:$E$1001,M$4)) | N9: =IF(SUMIFS('Input Sheet'!$F$3:$F$1001,'Input Sheet'!$B$3:$B$1001,$H9,'Input Sheet'!$E$3:$E$1001,N$4)=0,"",SUMIFS('Input Sheet'!$F$3:$F$1001,'Input Sheet'!$B$3:$B$1001,$H9,'Input Sheet'!$E$3:$E$1001,N$4)) | O9: =IF(SUMIFS('Input Sheet'!$F$3:$F$1001,'Input Sheet'!$B$3:$B$1001,$H9,'Input Sheet'!$E$3:$E$1001,O$4)=0,"",SUMIFS('Input Sheet'!$F$3:$F$1001,'Input Sheet'!$B$3:$B$1001,$H9,'Input Sheet'!$E$3:$E$1001,O$4)) | P9: =IF(SUMIFS('Input Sheet'!$F$3:$F$1001,'Input Sheet'!$B$3:$B$1001,$H9,'Input Sheet'!$E$3:$E$1001,P$4)=0,"",SUMIFS('Input Sheet'!$F$3:$F$1001,'Input Sheet'!$B$3:$B$1001,$H9,'Input Sheet'!$E$3:$E$1001,P$4)) | Q9: =IF(SUMIFS('Input Sheet'!$F$3:$F$1001,'Input Sheet'!$B$3:$B$1001,$H9,'Input Sheet'!$E$3:$E$1001,Q$4)=0,"",SUMIFS('Input Sheet'!$F$3:$F$1001,'Input Sheet'!$B$3:$B$1001,$H9,'Input Sheet'!$E$3:$E$1001,Q$4)) | R9: =IF(SUMIFS('Input Sheet'!$F$3:$F$1001,'Input Sheet'!$B$3:$B$1001,$H9,'Input Sheet'!$E$3:$E$1001,R$4)=0,"",SUMIFS('Input Sheet'!$F$3:$F$1001,'Input Sheet'!$B$3:$B$1001,$H9,'Input Sheet'!$E$3:$E$1001,R$4)) | S9: =IF(SUMIFS('Input Sheet'!$F$3:$F$1001,'Input Sheet'!$B$3:$B$1001,$H9,'Input Sheet'!$E$3:$E$1001,S$4)=0,"",SUMIFS('Input Sheet'!$F$3:$F$1001,'Input Sheet'!$B$3:$B$1001,$H9,'Input Sheet'!$E$3:$E$1001,S$4)) | T9: 4 | U9: Application | V9: =SUM(P6:P1005) -> 10
A10: =IF('Input Sheet'!B7=0,"",'Input Sheet'!B7) -> Exponents | B10: =IFERROR(VLOOKUP(A10,$A11:A$1005,1,FALSE)=0,1) -> FALSE | C10: =SUMIF('Input Sheet'!B$3:B$1000,A10,'Input Sheet'!C$3:C$1000) -> 0 | D10: =SUMIF('Input Sheet'!B$3:B$1000,A10,'Input Sheet'!D$3:D$1000) -> 16 | E10: =IFERROR(RANK(K10,K$6:K$1004,1),"") | F10: =IFERROR(RANK(L10,L$6:L$1004,1),"") | G10: =IFERROR(RANK(L10,L$6:L$1004,0),"") | H10: =IF($B10=1,$A10,"") | I10: =IF($B10=1,$C10,"") | J10: =IF($B10=1,$D10,"") | K10: =IF($B10=1,$C10/$D10+RAND()/1000,"") | L10: =IF($B10=1,$D10-$C10+RAND()/1000,"") | M10: =IF(SUMIFS('Input Sheet'!$F$3:$F$1001,'Input Sheet'!$B$3:$B$1001,$H10,'Input Sheet'!$E$3:$E$1001,M$4)=0,"",SUMIFS('Input Sheet'!$F$3:$F$1001,'Input Sheet'!$B$3:$B$1001,$H10,'Input Sheet'!$E$3:$E$1001,M$4)) | N10: =IF(SUMIFS('Input Sheet'!$F$3:$F$1001,'Input Sheet'!$B$3:$B$1001,$H10,'Input Sheet'!$E$3:$E$1001,N$4)=0,"",SUMIFS('Input Sheet'!$F$3:$F$1001,'Input Sheet'!$B$3:$B$1001,$H10,'Input Sheet'!$E$3:$E$1001,N$4)) | O10: =IF(SUMIFS('Input Sheet'!$F$3:$F$1001,'Input Sheet'!$B$3:$B$1001,$H10,'Input Sheet'!$E$3:$E$1001,O$4)=0,"",SUMIFS('Input Sheet'!$F$3:$F$1001,'Input Sheet'!$B$3:$B$1001,$H10,'Input Sheet'!$E$3:$E$1001,O$4)) | P10: =IF(SUMIFS('Input Sheet'!$F$3:$F$1001,'Input Sheet'!$B$3:$B$1001,$H10,'Input Sheet'!$E$3:$E$1001,P$4)=0,"",SUMIFS('Input Sheet'!$F$3:$F$1001,'Input Sheet'!$B$3:$B$1001,$H10,'Input Sheet'!$E$3:$E$1001,P$4)) | Q10: =IF(SUMIFS('Input Sheet'!$F$3:$F$1001,'Input Sheet'!$B$3:$B$1001,$H10,'Input Sheet'!$E$3:$E$1001,Q$4)=0,"",SUMIFS('Input Sheet'!$F$3:$F$1001,'Input Sheet'!$B$3:$B$1001,$H10,'Input Sheet'!$E$3:$E$1001,Q$4)) | R10: =IF(SUMIFS('Input Sheet'!$F$3:$F$1001,'Input Sheet'!$B$3:$B$1001,$H10,'Input Sheet'!$E$3:$E$1001,R$4)=0,"",SUMIFS('Input Sheet'!$F$3:$F$1001,'Input Sheet'!$B$3:$B$1001,$H10,'Input Sheet'!$E$3:$E$1001,R$4)) | S10: =IF(SUMIFS('Input Sheet'!$F$3:$F$1001,'Input Sheet'!$B$3:$B$1001,$H10,'Input Sheet'!$E$3:$E$1001,S$4)=0,"",SUMIFS('Input Sheet'!$F$3:$F$1001,'Input Sheet'!$B$3:$B$1001,$H10,'Input Sheet'!$E$3:$E$1001,S$4)) | T10: 5 | U10: Test Procedure | V10: =SUM(Q6:Q1005) -> 2
A11: =IF('Input Sheet'!B8=0,"",'Input Sheet'!B8) -> Algebraic Expressions | B11: =IFERROR(VLOOKUP(A11,$A12:A$1005,1,FALSE)=0,1) -> FALSE | C11: =SUMIF('Input Sheet'!B$3:B$1000,A11,'Input Sheet'!C$3:C$1000) -> 0 | D11: =SUMIF('Input Sheet'!B$3:B$1000,A11,'Input Sheet'!D$3:D$1000) -> 8 | E11: =IFERROR(RANK(K11,K$6:K$1004,1),"") | F11: =IFERROR(RANK(L11,L$6:L$1004,1),"") | G11: =IFERROR(RANK(L11,L$6:L$1004,0),"") | H11: =IF($B11=1,$A11,"") | I11: =IF($B11=1,$C11,"") | J11: =IF($B11=1,$D11,"") | K11: =IF($B11=1,$C11/$D11+RAND()/1000,"") | L11: =IF($B11=1,$D11-$C11+RAND()/1000,"") | M11: =IF(SUMIFS('Input Sheet'!$F$3:$F$1001,'Input Sheet'!$B$3:$B$1001,$H11,'Input Sheet'!$E$3:$E$1001,M$4)=0,"",SUMIFS('Input Sheet'!$F$3:$F$1001,'Input Sheet'!$B$3:$B$1001,$H11,'Input Sheet'!$E$3:$E$1001,M$4)) | N11: =IF(SUMIFS('Input Sheet'!$F$3:$F$1001,'Input Sheet'!$B$3:$B$1001,$H11,'Input Sheet'!$E$3:$E$1001,N$4)=0,"",SUMIFS('Input Sheet'!$F$3:$F$1001,'Input Sheet'!$B$3:$B$1001,$H11,'Input Sheet'!$E$3:$E$1001,N$4)) | O11: =IF(SUMIFS('Input Sheet'!$F$3:$F$1001,'Input Sheet'!$B$3:$B$1001,$H11,'Input Sheet'!$E$3:$E$1001,O$4)=0,"",SUMIFS('Input Sheet'!$F$3:$F$1001,'Input Sheet'!$B$3:$B$1001,$H11,'Input Sheet'!$E$3:$E$1001,O$4)) | P11: =IF(SUMIFS('Input Sheet'!$F$3:$F$1001,'Input Sheet'!$B$3:$B$1001,$H11,'Input Sheet'!$E$3:$E$1001,P$4)=0,"",SUMIFS('Input Sheet'!$F$3:$F$1001,'Input Sheet'!$B$3:$B$1001,$H11,'Input Sheet'!$E$3:$E$1001,P$4)) | Q11: =IF(SUMIFS('Input Sheet'!$F$3:$F$1001,'Input Sheet'!$B$3:$B$1001,$H11,'Input Sheet'!$E$3:$E$1001,Q$4)=0,"",SUMIFS('Input Sheet'!$F$3:$F$1001,'Input Sheet'!$B$3:$B$1001,$H11,'Input Sheet'!$E$3:$E$1001,Q$4)) | R11: =IF(SUMIFS('Input Sheet'!$F$3:$F$1001,'Input Sheet'!$B$3:$B$1001,$H11,'Input Sheet'!$E$3:$E$1001,R$4)=0,"",SUMIFS('Input Sheet'!$F$3:$F$1001,'Input Sheet'!$B$3:$B$1001,$H11,'Input Sheet'!$E$3:$E$1001,R$4)) | S11: =IF(SUMIFS('Input Sheet'!$F$3:$F$1001,'Input Sheet'!$B$3:$B$1001,$H11,'Input Sheet'!$E$3:$E$1001,S$4)=0,"",SUMIFS('Input Sheet'!$F$3:$F$1001,'Input Sheet'!$B$3:$B$1001,$H11,'Input Sheet'!$E$3:$E$1001,S$4)) | T11: 6 | U11: Omission | V11: =SUM(R6:R1005) -> 1
A12: =IF('Input Sheet'!B9=0,"",'Input Sheet'!B9) -> Number Patterns | B12: =IFERROR(VLOOKUP(A12,$A13:A$1005,1,FALSE)=0,1) -> FALSE | C12: =SUMIF('Input Sheet'!B$3:B$1000,A12,'Input Sheet'!C$3:C$1000) -> 6 | D12: =SUMIF('Input Sheet'!B$3:B$1000,A12,'Input Sheet'!D$3:D$1000) -> 18 | E12: =IFERROR(RANK(K12,K$6:K$1004,1),"") | F12: =IFERROR(RANK(L12,L$6:L$1004,1),"") | G12: =IFERROR(RANK(L12,L$6:L$1004,0),"") | H12: =IF($B12=1,$A12,"") | I12: =IF($B12=1,$C12,"") | J12: =IF($B12=1,$D12,"") | K12: =IF($B12=1,$C12/$D12+RAND()/1000,"") | L12: =IF($B12=1,$D12-$C12+RAND()/1000,"") | M12: =IF(SUMIFS('Input Sheet'!$F$3:$F$1001,'Input Sheet'!$B$3:$B$1001,$H12,'Input Sheet'!$E$3:$E$1001,M$4)=0,"",SUMIFS('Input Sheet'!$F$3:$F$1001,'Input Sheet'!$B$3:$B$1001,$H12,'Input Sheet'!$E$3:$E$1001,M$4)) | N12: =IF(SUMIFS('Input Sheet'!$F$3:$F$1001,'Input Sheet'!$B$3:$B$1001,$H12,'Input Sheet'!$E$3:$E$1001,N$4)=0,"",SUMIFS('Input Sheet'!$F$3:$F$1001,'Input Sheet'!$B$3:$B$1001,$H12,'Input Sheet'!$E$3:$E$1001,N$4)) | O12: =IF(SUMIFS('Input Sheet'!$F$3:$F$1001,'Input Sheet'!$B$3:$B$1001,$H12,'Input Sheet'!$E$3:$E$1001,O$4)=0,"",SUMIFS('Input Sheet'!$F$3:$F$1001,'Input Sheet'!$B$3:$B$1001,$H12,'Input Sheet'!$E$3:$E$1001,O$4)) | P12: =IF(SUMIFS('Input Sheet'!$F$3:$F$1001,'Input Sheet'!$B$3:$B$1001,$H12,'Input Sheet'!$E$3:$E$1001,P$4)=0,"",SUMIFS('Input Sheet'!$F$3:$F$1001,'Input Sheet'!$B$3:$B$1001,$H12,'Input Sheet'!$E$3:$E$1001,P$4)) | Q12: =IF(SUMIFS('Input Sheet'!$F$3:$F$1001,'Input Sheet'!$B$3:$B$1001,$H12,'Input Sheet'!$E$3:$E$1001,Q$4)=0,"",SUMIFS('Input Sheet'!$F$3:$F$1001,'Input Sheet'!$B$3:$B$1001,$H12,'Input Sheet'!$E$3:$E$1001,Q$4)) | R12: =IF(SUMIFS('Input Sheet'!$F$3:$F$1001,'Input Sheet'!$B$3:$B$1001,$H12,'Input Sheet'!$E$3:$E$1001,R$4)=0,"",SUMIFS('Input Sheet'!$F$3:$F$1001,'Input Sheet'!$B$3:$B$1001,$H12,'Input Sheet'!$E$3:$E$1001,R$4)) | S12: =IF(SUMIFS('Input Sheet'!$F$3:$F$1001,'Input Sheet'!$B$3:$B$1001,$H12,'Input Sheet'!$E$3:$E$1001,S$4)=0,"",SUMIFS('Input Sheet'!$F$3:$F$1001,'Input Sheet'!$B$3:$B$1001,$H12,'Input Sheet'!$E$3:$E$1001,S$4)) | T12: 7 | U12: No error
A13: =IF('Input Sheet'!B10=0,"",'Input Sheet'!B10) -> Number Patterns | B13: =IFERROR(VLOOKUP(A13,$A14:A$1005,1,FALSE)=0,1) -> FALSE | C13: =SUMIF('Input Sheet'!B$3:B$1000,A13,'Input Sheet'!C$3:C$1000) -> 6 | D13: =SUMIF('Input Sheet'!B$3:B$1000,A13,'Input Sheet'!D$3:D$1000) -> 18 | E13: =IFERROR(RANK(K13,K$6:K$1004,1),"") | F13: =IFERROR(RANK(L13,L$6:L$1004,1),"") | G13: =IFERROR(RANK(L13,L$6:L$1004,0),"") | H13: =IF($B13=1,$A13,"") | I13: =IF($B13=1,$C13,"") | J13: =IF($B13=1,$D13,"") | K13: =IF($B13=1,$C13/$D13+RAND()/1000,"") | L13: =IF($B13=1,$D13-$C13+RAND()/1000,"") | M13: =IF(SUMIFS('Input Sheet'!$F$3:$F$1001,'Input Sheet'!$B$3:$B$1001,$H13,'Input Sheet'!$E$3:$E$1001,M$4)=0,"",SUMIFS('Input Sheet'!$F$3:$F$1001,'Input Sheet'!$B$3:$B$1001,$H13,'Input Sheet'!$E$3:$E$1001,M$4)) | N13: =IF(SUMIFS('Input Sheet'!$F$3:$F$1001,'Input Sheet'!$B$3:$B$1001,$H13,'Input Sheet'!$E$3:$E$1001,N$4)=0,"",SUMIFS('Input Sheet'!$F$3:$F$1001,'Input Sheet'!$B$3:$B$1001,$H13,'Input Sheet'!$E$3:$E$1001,N$4)) | O13: =IF(SUMIFS('Input Sheet'!$F$3:$F$1001,'Input Sheet'!$B$3:$B$1001,$H13,'Input Sheet'!$E$3:$E$1001,O$4)=0,"",SUMIFS('Input Sheet'!$F$3:$F$1001,'Input Sheet'!$B$3:$B$1001,$H13,'Input Sheet'!$E$3:$E$1001,O$4)) | P13: =IF(SUMIFS('Input Sheet'!$F$3:$F$1001,'Input Sheet'!$B$3:$B$1001,$H13,'Input Sheet'!$E$3:$E$1001,P$4)=0,"",SUMIFS('Input Sheet'!$F$3:$F$1001,'Input Sheet'!$B$3:$B$1001,$H13,'Input Sheet'!$E$3:$E$1001,P$4)) | Q13: =IF(SUMIFS('Input Sheet'!$F$3:$F$1001,'Input Sheet'!$B$3:$B$1001,$H13,'Input Sheet'!$E$3:$E$1001,Q$4)=0,"",SUMIFS('Input Sheet'!$F$3:$F$1001,'Input Sheet'!$B$3:$B$1001,$H13,'Input Sheet'!$E$3:$E$1001,Q$4)) | R13: =IF(SUMIFS('Input Sheet'!$F$3:$F$1001,'Input Sheet'!$B$3:$B$1001,$H13,'Input Sheet'!$E$3:$E$1001,R$4)=0,"",SUMIFS('Input Sheet'!$F$3:$F$1001,'Input Sheet'!$B$3:$B$1001,$H13,'Input Sheet'!$E$3:$E$1001,R$4)) | S13: =IF(SUMIFS('Input Sheet'!$F$3:$F$1001,'Input Sheet'!$B$3:$B$1001,$H13,'Input Sheet'!$E$3:$E$1001,S$4)=0,"",SUMIFS('Input Sheet'!$F$3:$F$1001,'Input Sheet'!$B$3:$B$1001,$H13,'Input Sheet'!$E$3:$E$1001,S$4)) | T13: 8
A14: =IF('Input Sheet'!B11=0,"",'Input Sheet'!B11) -> Number Patterns | B14: =IFERROR(VLOOKUP(A14,$A15:A$1005,1,FALSE)=0,1) -> 1 | C14: =SUMIF('Input Sheet'!B$3:B$1000,A14,'Input Sheet'!C$3:C$1000) -> 6 | D14: =SUMIF('Input Sheet'!B$3:B$1000,A14,'Input Sheet'!D$3:D$1000) -> 18 | E14: =IFERROR(RANK(K14,K$6:K$1004,1),"") -> 3 | F14: =IFERROR(RANK(L14,L$6:L$1004,1),"") -> 4 | G14: =IFERROR(RANK(L14,L$6:L$1004,0),"") -> 2 | H14: =IF($B14=1,$A14,"") -> Number Patterns | I14: =IF($B14=1,$C14,"") -> 6 | J14: =IF($B14=1,$D14,"") -> 18 | K14: =IF($B14=1,$C14/$D14+RAND()/1000,"") -> 0.33360771 | L14: =IF($B14=1,$D14-$C14+RAND()/1000,"") -> 12.000444 | M14: =IF(SUMIFS('Input Sheet'!$F$3:$F$1001,'Input Sheet'!$B$3:$B$1001,$H14,'Input Sheet'!$E$3:$E$1001,M$4)=0,"",SUMIFS('Input Sheet'!$F$3:$F$1001,'Input Sheet'!$B$3:$B$1001,$H14,'Input Sheet'!$E$3:$E$1001,M$4)) | N14: =IF(SUMIFS('Input Sheet'!$F$3:$F$1001,'Input Sheet'!$B$3:$B$1001,$H14,'Input Sheet'!$E$3:$E$1001,N$4)=0,"",SUMIFS('Input Sheet'!$F$3:$F$1001,'Input Sheet'!$B$3:$B$1001,$H14,'Input Sheet'!$E$3:$E$1001,N$4)) | O14: =IF(SUMIFS('Input Sheet'!$F$3:$F$1001,'Input Sheet'!$B$3:$B$1001,$H14,'Input Sheet'!$E$3:$E$1001,O$4)=0,"",SUMIFS('Input Sheet'!$F$3:$F$1001,'Input Sheet'!$B$3:$B$1001,$H14,'Input Sheet'!$E$3:$E$1001,O$4)) -> 10 | P14: =IF(SUMIFS('Input Sheet'!$F$3:$F$1001,'Input Sheet'!$B$3:$B$1001,$H14,'Input Sheet'!$E$3:$E$1001,P$4)=0,"",SUMIFS('Input Sheet'!$F$3:$F$1001,'Input Sheet'!$B$3:$B$1001,$H14,'Input Sheet'!$E$3:$E$1001,P$4)) -> 2 | Q14: =IF(SUMIFS('Input Sheet'!$F$3:$F$1001,'Input Sheet'!$B$3:$B$1001,$H14,'Input Sheet'!$E$3:$E$1001,Q$4)=0,"",SUMIFS('Input Sheet'!$F$3:$F$1001,'Input Sheet'!$B$3:$B$1001,$H14,'Input Sheet'!$E$3:$E$1001,Q$4)) | R14: =IF(SUMIFS('Input Sheet'!$F$3:$F$1001,'Input Sheet'!$B$3:$B$1001,$H14,'Input Sheet'!$E$3:$E$1001,R$4)=0,"",SUMIFS('Input Sheet'!$F$3:$F$1001,'Input Sheet'!$B$3:$B$1001,$H14,'Input Sheet'!$E$3:$E$1001,R$4)) | S14: =IF(SUMIFS('Input Sheet'!$F$3:$F$1001,'Input Sheet'!$B$3:$B$1001,$H14,'Input Sheet'!$E$3:$E$1001,S$4)=0,"",SUMIFS('Input Sheet'!$F$3:$F$1001,'Input Sheet'!$B$3:$B$1001,$H14,'Input Sheet'!$E$3:$E$1001,S$4)) | T14: 9
A15: =IF('Input Sheet'!B12=0,"",'Input Sheet'!B12) -> Exponents | B15: =IFERROR(VLOOKUP(A15,$A16:A$1005,1,FALSE)=0,1) -> FALSE | C15: =SUMIF('Input Sheet'!B$3:B$1000,A15,'Input Sheet'!C$3:C$1000) -> 0 | D15: =SUMIF('Input Sheet'!B$3:B$1000,A15,'Input Sheet'!D$3:D$1000) -> 16 | E15: =IFERROR(RANK(K15,K$6:K$1004,1),"") | F15: =IFERROR(RANK(L15,L$6:L$1004,1),"") | G15: =IFERROR(RANK(L15,L$6:L$1004,0),"") | H15: =IF($B15=1,$A15,"") | I15: =IF($B15=1,$C15,"") | J15: =IF($B15=1,$D15,"") | K15: =IF($B15=1,$C15/$D15+RAND()/1000,"") | L15: =IF($B15=1,$D15-$C15+RAND()/1000,"") | M15: =IF(SUMIFS('Input Sheet'!$F$3:$F$1001,'Input Sheet'!$B$3:$B$1001,$H15,'Input Sheet'!$E$3:$E$1001,M$4)=0,"",SUMIFS('Input Sheet'!$F$3:$F$1001,'Input Sheet'!$B$3:$B$1001,$H15,'Input Sheet'!$E$3:$E$1001,M$4)) | N15: =IF(SUMIFS('Input Sheet'!$F$3:$F$1001,'Input Sheet'!$B$3:$B$1001,$H15,'Input Sheet'!$E$3:$E$1001,N$4)=0,"",SUMIFS('Input Sheet'!$F$3:$F$1001,'Input Sheet'!$B$3:$B$1001,$H15,'Input Sheet'!$E$3:$E$1001,N$4)) | O15: =IF(SUMIFS('Input Sheet'!$F$3:$F$1001,'Input Sheet'!$B$3:$B$1001,$H15,'Input Sheet'!$E$3:$E$1001,O$4)=0,"",SUMIFS('Input Sheet'!$F$3:$F$1001,'Input Sheet'!$B$3:$B$1001,$H15,'Input Sheet'!$E$3:$E$1001,O$4)) | P15: =IF(SUMIFS('Input Sheet'!$F$3:$F$1001,'Input Sheet'!$B$3:$B$1001,$H15,'Input Sheet'!$E$3:$E$1001,P$4)=0,"",SUMIFS('Input Sheet'!$F$3:$F$1001,'Input Sheet'!$B$3:$B$1001,$H15,'Input Sheet'!$E$3:$E$1001,P$4)) | Q15: =IF(SUMIFS('Input Sheet'!$F$3:$F$1001,'Input Sheet'!$B$3:$B$1001,$H15,'Input Sheet'!$E$3:$E$1001,Q$4)=0,"",SUMIFS('Input Sheet'!$F$3:$F$1001,'Input Sheet'!$B$3:$B$1001,$H15,'Input Sheet'!$E$3:$E$1001,Q$4)) | R15: =IF(SUMIFS('Input Sheet'!$F$3:$F$1001,'Input Sheet'!$B$3:$B$1001,$H15,'Input Sheet'!$E$3:$E$1001,R$4)=0,"",SUMIFS('Input Sheet'!$F$3:$F$1001,'Input Sheet'!$B$3:$B$1001,$H15,'Input Sheet'!$E$3:$E$1001,R$4)) | S15: =IF(SUMIFS('Input Sheet'!$F$3:$F$1001,'Input Sheet'!$B$3:$B$1001,$H15,'Input Sheet'!$E$3:$E$1001,S$4)=0,"",SUMIFS('Input Sheet'!$F$3:$F$1001,'Input Sheet'!$B$3:$B$1001,$H15,'Input Sheet'!$E$3:$E$1001,S$4)) | T15: 10
A16: =IF('Input Sheet'!B13=0,"",'Input Sheet'!B13) -> Exponents | B16: =IFERROR(VLOOKUP(A16,$A17:A$1005,1,FALSE)=0,1) -> FALSE | C16: =SUMIF('Input Sheet'!B$3:B$1000,A16,'Input Sheet'!C$3:C$1000) -> 0 | D16: =SUMIF('Input Sheet'!B$3:B$1000,A16,'Input Sheet'!D$3:D$1000) -> 16 | E16: =IFERROR(RANK(K16,K$6:K$1004,1),"") | F16: =IFERROR(RANK(L16,L$6:L$1004,1),"") | G16: =IFERROR(RANK(L16,L$6:L$1004,0),"") | H16: =IF($B16=1,$A16,"") | I16: =IF($B16=1,$C16,"") | J16: =IF($B16=1,$D16,"") | K16: =IF($B16=1,$C16/$D16+RAND()/1000,"") | L16: =IF($B16=1,$D16-$C16+RAND()/1000,"") | M16: =IF(SUMIFS('Input Sheet'!$F$3:$F$1001,'Input Sheet'!$B$3:$B$1001,$H16,'Input Sheet'!$E$3:$E$1001,M$4)=0,"",SUMIFS('Input Sheet'!$F$3:$F$1001,'Input Sheet'!$B$3:$B$1001,$H16,'Input Sheet'!$E$3:$E$1001,M$4)) | N16: =IF(SUMIFS('Input Sheet'!$F$3:$F$1001,'Input Sheet'!$B$3:$B$1001,$H16,'Input Sheet'!$E$3:$E$1001,N$4)=0,"",SUMIFS('Input Sheet'!$F$3:$F$1001,'Input Sheet'!$B$3:$B$1001,$H16,'Input Sheet'!$E$3:$E$1001,N$4)) | O16: =IF(SUMIFS('Input Sheet'!$F$3:$F$1001,'Input Sheet'!$B$3:$B$1001,$H16,'Input Sheet'!$E$3:$E$1001,O$4)=0,"",SUMIFS('Input Sheet'!$F$3:$F$1001,'Input Sheet'!$B$3:$B$1001,$H16,'Input Sheet'!$E$3:$E$1001,O$4)) | P16: =IF(SUMIFS('Input Sheet'!$F$3:$F$1001,'Input Sheet'!$B$3:$B$1001,$H16,'Input Sheet'!$E$3:$E$1001,P$4)=0,"",SUMIFS('Input Sheet'!$F$3:$F$1001,'Input Sheet'!$B$3:$B$1001,$H16,'Input Sheet'!$E$3:$E$1001,P$4)) | Q16: =IF(SUMIFS('Input Sheet'!$F$3:$F$1001,'Input Sheet'!$B$3:$B$1001,$H16,'Input Sheet'!$E$3:$E$1001,Q$4)=0,"",SUMIFS('Input Sheet'!$F$3:$F$1001,'Input Sheet'!$B$3:$B$1001,$H16,'Input Sheet'!$E$3:$E$1001,Q$4)) | R16: =IF(SUMIFS('Input Sheet'!$F$3:$F$1001,'Input Sheet'!$B$3:$B$1001,$H16,'Input Sheet'!$E$3:$E$1001,R$4)=0,"",SUMIFS('Input Sheet'!$F$3:$F$1001,'Input Sheet'!$B$3:$B$1001,$H16,'Input Sheet'!$E$3:$E$1001,R$4)) | S16: =IF(SUMIFS('Input Sheet'!$F$3:$F$1001,'Input Sheet'!$B$3:$B$1001,$H16,'Input Sheet'!$E$3:$E$1001,S$4)=0,"",SUMIFS('Input Sheet'!$F$3:$F$1001,'Input Sheet'!$B$3:$B$1001,$H16,'Input Sheet'!$E$3:$E$1001,S$4)) | T16: 11
A17: =IF('Input Sheet'!B14=0,"",'Input Sheet'!B14) -> Algebraic Expressions | B17: =IFERROR(VLOOKUP(A17,$A18:A$1005,1,FALSE)=0,1) -> 1 | C17: =SUMIF('Input Sheet'!B$3:B$1000,A17,'Input Sheet'!C$3:C$1000) -> 0 | D17: =SUMIF('Input Sheet'!B$3:B$1000,A17,'Input Sheet'!D$3:D$1000) -> 8 | E17: =IFERROR(RANK(K17,K$6:K$1004,1),"") -> 1 | F17: =IFERROR(RANK(L17,L$6:L$1004,1),"") -> 3 | G17: =IFERROR(RANK(L17,L$6:L$1004,0),"") -> 3 | H17: =IF($B17=1,$A17,"") -> Algebraic Expressions | I17: =IF($B17=1,$C17,"") -> 0 | J17: =IF($B17=1,$D17,"") -> 8 | K17: =IF($B17=1,$C17/$D17+RAND()/1000,"") -> 0.00057586571 | L17: =IF($B17=1,$D17-$C17+RAND()/1000,"") -> 8.0004157 | M17: =IF(SUMIFS('Input Sheet'!$F$3:$F$1001,'Input Sheet'!$B$3:$B$1001,$H17,'Input Sheet'!$E$3:$E$1001,M$4)=0,"",SUMIFS('Input Sheet'!$F$3:$F$1001,'Input Sheet'!$B$3:$B$1001,$H17,'Input Sheet'!$E$3:$E$1001,M$4)) | N17: =IF(SUMIFS('Input Sheet'!$F$3:$F$1001,'Input Sheet'!$B$3:$B$1001,$H17,'Input Sheet'!$E$3:$E$1001,N$4)=0,"",SUMIFS('Input Sheet'!$F$3:$F$1001,'Input Sheet'!$B$3:$B$1001,$H17,'Input Sheet'!$E$3:$E$1001,N$4)) | O17: =IF(SUMIFS('Input Sheet'!$F$3:$F$1001,'Input Sheet'!$B$3:$B$1001,$H17,'Input Sheet'!$E$3:$E$1001,O$4)=0,"",SUMIFS('Input Sheet'!$F$3:$F$1001,'Input Sheet'!$B$3:$B$1001,$H17,'Input Sheet'!$E$3:$E$1001,O$4)) | P17: =IF(SUMIFS('Input Sheet'!$F$3:$F$1001,'Input Sheet'!$B$3:$B$1001,$H17,'Input Sheet'!$E$3:$E$1001,P$4)=0,"",SUMIFS('Input Sheet'!$F$3:$F$1001,'Input Sheet'!$B$3:$B$1001,$H17,'Input Sheet'!$E$3:$E$1001,P$4)) -> 8 | Q17: =IF(SUMIFS('Input Sheet'!$F$3:$F$1001,'Input Sheet'!$B$3:$B$1001,$H17,'Input Sheet'!$E$3:$E$1001,Q$4)=0,"",SUMIFS('Input Sheet'!$F$3:$F$1001,'Input Sheet'!$B$3:$B$1001,$H17,'Input Sheet'!$E$3:$E$1001,Q$4)) | R17: =IF(SUMIFS('Input Sheet'!$F$3:$F$1001,'Input Sheet'!$B$3:$B$1001,$H17,'Input Sheet'!$E$3:$E$1001,R$4)=0,"",SUMIFS('Input Sheet'!$F$3:$F$1001,'Input Sheet'!$B$3:$B$1001,$H17,'Input Sheet'!$E$3:$E$1001,R$4)) | S17: =IF(SUMIFS('Input Sheet'!$F$3:$F$1001,'Input Sheet'!$B$3:$B$1001,$H17,'Input Sheet'!$E$3:$E$1001,S$4)=0,"",SUMIFS('Input Sheet'!$F$3:$F$1001,'Input Sheet'!$B$3:$B$1001,$H17,'Input Sheet'!$E$3:$E$1001,S$4)) | T17: 12
A18: =IF('Input Sheet'!B15=0,"",'Input Sheet'!B15) -> Functions | B18: =IFERROR(VLOOKUP(A18,$A19:A$1005,1,FALSE)=0,1) -> 1 | C18: =SUMIF('Input Sheet'!B$3:B$1000,A18,'Input Sheet'!C$3:C$1000) -> 6 | D18: =SUMIF('Input Sheet'!B$3:B$1000,A18,'Input Sheet'!D$3:D$1000) -> 8 | E18: =IFERROR(RANK(K18,K$6:K$1004,1),"") -> 4 | F18: =IFERROR(RANK(L18,L$6:L$1004,1),"") -> 2 | G18: =IFERROR(RANK(L18,L$6:L$1004,0),"") -> 4 | H18: =IF($B18=1,$A18,"") -> Functions | I18: =IF($B18=1,$C18,"") -> 6 | J18: =IF($B18=1,$D18,"") -> 8 | K18: =IF($B18=1,$C18/$D18+RAND()/1000,"") -> 0.75057299 | L18: =IF($B18=1,$D18-$C18+RAND()/1000,"") -> 2.0003635 | M18: =IF(SUMIFS('Input Sheet'!$F$3:$F$1001,'Input Sheet'!$B$3:$B$1001,$H18,'Input Sheet'!$E$3:$E$1001,M$4)=0,"",SUMIFS('Input Sheet'!$F$3:$F$1001,'Input Sheet'!$B$3:$B$1001,$H18,'Input Sheet'!$E$3:$E$1001,M$4)) | N18: =IF(SUMIFS('Input Sheet'!$F$3:$F$1001,'Input Sheet'!$B$3:$B$1001,$H18,'Input Sheet'!$E$3:$E$1001,N$4)=0,"",SUMIFS('Input Sheet'!$F$3:$F$1001,'Input Sheet'!$B$3:$B$1001,$H18,'Input Sheet'!$E$3:$E$1001,N$4)) | O18: =IF(SUMIFS('Input Sheet'!$F$3:$F$1001,'Input Sheet'!$B$3:$B$1001,$H18,'Input Sheet'!$E$3:$E$1001,O$4)=0,"",SUMIFS('Input Sheet'!$F$3:$F$1001,'Input Sheet'!$B$3:$B$1001,$H18,'Input Sheet'!$E$3:$E$1001,O$4)) -> 2 | P18: =IF(SUMIFS('Input Sheet'!$F$3:$F$1001,'Input Sheet'!$B$3:$B$1001,$H18,'Input Sheet'!$E$3:$E$1001,P$4)=0,"",SUMIFS('Input Sheet'!$F$3:$F$1001,'Input Sheet'!$B$3:$B$1001,$H18,'Input Sheet'!$E$3:$E$1001,P$4)) | Q18: =IF(SUMIFS('Input Sheet'!$F$3:$F$1001,'Input Sheet'!$B$3:$B$1001,$H18,'Input Sheet'!$E$3:$E$1001,Q$4)=0,"",SUMIFS('Input Sheet'!$F$3:$F$1001,'Input Sheet'!$B$3:$B$1001,$H18,'Input Sheet'!$E$3:$E$1001,Q$4)) | R18: =IF(SUMIFS('Input Sheet'!$F$3:$F$1001,'Input Sheet'!$B$3:$B$1001,$H18,'Input Sheet'!$E$3:$E$1001,R$4)=0,"",SUMIFS('Input Sheet'!$F$3:$F$1001,'Input Sheet'!$B$3:$B$1001,$H18,'Input Sheet'!$E$3:$E$1001,R$4)) | S18: =IF(SUMIFS('Input Sheet'!$F$3:$F$1001,'Input Sheet'!$B$3:$B$1001,$H18,'Input Sheet'!$E$3:$E$1001,S$4)=0,"",SUMIFS('Input Sheet'!$F$3:$F$1001,'Input Sheet'!$B$3:$B$1001,$H18,'Input Sheet'!$E$3:$E$1001,S$4)) | T18: 13
A19: =IF('Input Sheet'!B16=0,"",'Input Sheet'!B16) -> Trigonometry | B19: =IFERROR(VLOOKUP(A19,$A20:A$1005,1,FALSE)=0,1) -> 1 | C19: =SUMIF('Input Sheet'!B$3:B$1000,A19,'Input Sheet'!C$3:C$1000) -> 4 | D19: =SUMIF('Input Sheet'!B$3:B$1000,A19,'Input Sheet'!D$3:D$1000) -> 5 | E19: =IFERROR(RANK(K19,K$6:K$1004,1),"") -> 5 | F19: =IFERROR(RANK(L19,L$6:L$1004,1),"") -> 1 | G19: =IFERROR(RANK(L19,L$6:L$1004,0),"") -> 5 | H19: =IF($B19=1,$A19,"") -> Trigonometry | I19: =IF($B19=1,$C19,"") -> 4 | J19: =IF($B19=1,$D19,"") -> 5 | K19: =IF($B19=1,$C19/$D19+RAND()/1000,"") -> 0.80038396 | L19: =IF($B19=1,$D19-$C19+RAND()/1000,"") -> 1.0004049 | M19: =IF(SUMIFS('Input Sheet'!$F$3:$F$1001,'Input Sheet'!$B$3:$B$1001,$H19,'Input Sheet'!$E$3:$E$1001,M$4)=0,"",SUMIFS('Input Sheet'!$F$3:$F$1001,'Input Sheet'!$B$3:$B$1001,$H19,'Input Sheet'!$E$3:$E$1001,M$4)) | N19: =IF(SUMIFS('Input Sheet'!$F$3:$F$1001,'Input Sheet'!$B$3:$B$1001,$H19,'Input Sheet'!$E$3:$E$1001,N$4)=0,"",SUMIFS('Input Sheet'!$F$3:$F$1001,'Input Sheet'!$B$3:$B$1001,$H19,'Input Sheet'!$E$3:$E$1001,N$4)) | O19: =IF(SUMIFS('Input Sheet'!$F$3:$F$1001,'Input Sheet'!$B$3:$B$1001,$H19,'Input Sheet'!$E$3:$E$1001,O$4)=0,"",SUMIFS('Input Sheet'!$F$3:$F$1001,'Input Sheet'!$B$3:$B$1001,$H19,'Input Sheet'!$E$3:$E$1001,O$4)) | P19: =IF(SUMIFS('Input Sheet'!$F$3:$F$1001,'Input Sheet'!$B$3:$B$1001,$H19,'Input Sheet'!$E$3:$E$1001,P$4)=0,"",SUMIFS('Input Sheet'!$F$3:$F$1001,'Input Sheet'!$B$3:$B$1001,$H19,'Input Sheet'!$E$3:$E$1001,P$4)) | Q19: =IF(SUMIFS('Input Sheet'!$F$3:$F$1001,'Input Sheet'!$B$3:$B$1001,$H19,'Input Sheet'!$E$3:$E$1001,Q$4)=0,"",SUMIFS('Input Sheet'!$F$3:$F$1001,'Input Sheet'!$B$3:$B$1001,$H19,'Input Sheet'!$E$3:$E$1001,Q$4)) -> 1 | R19: =IF(SUMIFS('Input Sheet'!$F$3:$F$1001,'Input Sheet'!$B$3:$B$1001,$H19,'Input Sheet'!$E$3:$E$1001,R$4)=0,"",SUMIFS('Input Sheet'!$F$3:$F$1001,'Input Sheet'!$B$3:$B$1001,$H19,'Input Sheet'!$E$3:$E$1001,R$4)) | S19: =IF(SUMIFS('Input Sheet'!$F$3:$F$1001,'Input Sheet'!$B$3:$B$1001,$H19,'Input Sheet'!$E$3:$E$1001,S$4)=0,"",SUMIFS('Input Sheet'!$F$3:$F$1001,'Input Sheet'!$B$3:$B$1001,$H19,'Input Sheet'!$E$3:$E$1001,S$4)) | T19: 14
A20: =IF('Input Sheet'!B17=0,"",'Input Sheet'!B17) -> Exponents | B20: =IFERROR(VLOOKUP(A20,$A21:A$1005,1,FALSE)=0,1) -> FALSE | C20: =SUMIF('Input Sheet'!B$3:B$1000,A20,'Input Sheet'!C$3:C$1000) -> 0 | D20: =SUMIF('Input Sheet'!B$3:B$1000,A20,'Input Sheet'!D$3:D$1000) -> 16 | E20: =IFERROR(RANK(K20,K$6:K$1004,1),"") | F20: =IFERROR(RANK(L20,L$6:L$1004,1),"") | G20: =IFERROR(RANK(L20,L$6:L$1004,0),"") | H20: =IF($B20=1,$A20,"") | I20: =IF($B20=1,$C20,"") | J20: =IF($B20=1,$D20,"") | K20: =IF($B20=1,$C20/$D20+RAND()/1000,"") | L20: =IF($B20=1,$D20-$C20+RAND()/1000,"") | M20: =IF(SUMIFS('Input Sheet'!$F$3:$F$1001,'Input Sheet'!$B$3:$B$1001,$H20,'Input Sheet'!$E$3:$E$1001,M$4)=0,"",SUMIFS('Input Sheet'!$F$3:$F$1001,'Input Sheet'!$B$3:$B$1001,$H20,'Input Sheet'!$E$3:$E$1001,M$4)) | N20: =IF(SUMIFS('Input Sheet'!$F$3:$F$1001,'Input Sheet'!$B$3:$B$1001,$H20,'Input Sheet'!$E$3:$E$1001,N$4)=0,"",SUMIFS('Input Sheet'!$F$3:$F$1001,'Input Sheet'!$B$3:$B$1001,$H20,'Input Sheet'!$E$3:$E$1001,N$4)) | O20: =IF(SUMIFS('Input Sheet'!$F$3:$F$1001,'Input Sheet'!$B$3:$B$1001,$H20,'Input Sheet'!$E$3:$E$1001,O$4)=0,"",SUMIFS('Input Sheet'!$F$3:$F$1001,'Input Sheet'!$B$3:$B$1001,$H20,'Input Sheet'!$E$3:$E$1001,O$4)) | P20: =IF(SUMIFS('Input Sheet'!$F$3:$F$1001,'Input Sheet'!$B$3:$B$1001,$H20,'Input Sheet'!$E$3:$E$1001,P$4)=0,"",SUMIFS('Input Sheet'!$F$3:$F$1001,'Input Sheet'!$B$3:$B$1001,$H20,'Input Sheet'!$E$3:$E$1001,P$4)) | Q20: =IF(SUMIFS('Input Sheet'!$F$3:$F$1001,'Input Sheet'!$B$3:$B$1001,$H20,'Input Sheet'!$E$3:$E$1001,Q$4)=0,"",SUMIFS('Input Sheet'!$F$3:$F$1001,'Input Sheet'!$B$3:$B$1001,$H20,'Input Sheet'!$E$3:$E$1001,Q$4)) | R20: =IF(SUMIFS('Input Sheet'!$F$3:$F$1001,'Input Sheet'!$B$3:$B$1001,$H20,'Input Sheet'!$E$3:$E$1001,R$4)=0,"",SUMIFS('Input Sheet'!$F$3:$F$1001,'Input Sheet'!$B$3:$B$1001,$H20,'Input Sheet'!$E$3:$E$1001,R$4)) | S20: =IF(SUMIFS('Input Sheet'!$F$3:$F$1001,'Input Sheet'!$B$3:$B$1001,$H20,'Input Sheet'!$E$3:$E$1001,S$4)=0,"",SUMIFS('Input Sheet'!$F$3:$F$1001,'Input Sheet'!$B$3:$B$1001,$H20,'Input Sheet'!$E$3:$E$1001,S$4)) | T20: 15
A21: =IF('Input Sheet'!B18=0,"",'Input Sheet'!B18) -> Exponents | B21: =IFERROR(VLOOKUP(A21,$A22:A$1005,1,FALSE)=0,1) -> 1 | C21: =SUMIF('Input Sheet'!B$3:B$1000,A21,'Input Sheet'!C$3:C$1000) -> 0 | D21: =SUMIF('Input Sheet'!B$3:B$1000,A21,'Input Sheet'!D$3:D$1000) -> 16 | E21: =IFERROR(RANK(K21,K$6:K$1004,1),"") -> 2 | F21: =IFERROR(RANK(L21,L$6:L$1004,1),"") -> 5 | G21: =IFERROR(RANK(L21,L$6:L$1004,0),"") -> 1 | H21: =IF($B21=1,$A21,"") -> Exponents | I21: =IF($B21=1,$C21,"") -> 0 | J21: =IF($B21=1,$D21,"") -> 16 | K21: =IF($B21=1,$C21/$D21+RAND()/1000,"") -> 0.00081248237 | L21: =IF($B21=1,$D21-$C21+RAND()/1000,"") -> 16.000731 | M21: =IF(SUMIFS('Input Sheet'!$F$3:$F$1001,'Input Sheet'!$B$3:$B$1001,$H21,'Input Sheet'!$E$3:$E$1001,M$4)=0,"",SUMIFS('Input Sheet'!$F$3:$F$1001,'Input Sheet'!$B$3:$B$1001,$H21,'Input Sheet'!$E$3:$E$1001,M$4)) -> 8 | N21: =IF(SUMIFS('Input Sheet'!$F$3:$F$1001,'Input Sheet'!$B$3:$B$1001,$H21,'Input Sheet'!$E$3:$E$1001,N$4)=0,"",SUMIFS('Input Sheet'!$F$3:$F$1001,'Input Sheet'!$B$3:$B$1001,$H21,'Input Sheet'!$E$3:$E$1001,N$4)) -> 6 | O21: =IF(SUMIFS('Input Sheet'!$F$3:$F$1001,'Input Sheet'!$B$3:$B$1001,$H21,'Input Sheet'!$E$3:$E$1001,O$4)=0,"",SUMIFS('Input Sheet'!$F$3:$F$1001,'Input Sheet'!$B$3:$B$1001,$H21,'Input Sheet'!$E$3:$E$1001,O$4)) | P21: =IF(SUMIFS('Input Sheet'!$F$3:$F$1001,'Input Sheet'!$B$3:$B$1001,$H21,'Input Sheet'!$E$3:$E$1001,P$4)=0,"",SUMIFS('Input Sheet'!$F$3:$F$1001,'Input Sheet'!$B$3:$B$1001,$H21,'Input Sheet'!$E$3:$E$1001,P$4)) | Q21: =IF(SUMIFS('Input Sheet'!$F$3:$F$1001,'Input Sheet'!$B$3:$B$1001,$H21,'Input Sheet'!$E$3:$E$1001,Q$4)=0,"",SUMIFS('Input Sheet'!$F$3:$F$1001,'Input Sheet'!$B$3:$B$1001,$H21,'Input Sheet'!$E$3:$E$1001,Q$4)) -> 1 | R21: =IF(SUMIFS('Input Sheet'!$F$3:$F$1001,'Input Sheet'!$B$3:$B$1001,$H21,'Input Sheet'!$E$3:$E$1001,R$4)=0,"",SUMIFS('Input Sheet'!$F$3:$F$1001,'Input Sheet'!$B$3:$B$1001,$H21,'Input Sheet'!$E$3:$E$1001,R$4)) -> 1 | S21: =IF(SUMIFS('Input Sheet'!$F$3:$F$1001,'Input Sheet'!$B$3:$B$1001,$H21,'Input Sheet'!$E$3:$E$1001,S$4)=0,"",SUMIFS('Input Sheet'!$F$3:$F$1001,'Input Sheet'!$B$3:$B$1001,$H21,'Input Sheet'!$E$3:$E$1001,S$4)) | T21: 16
A22: =IF('Input Sheet'!B19=0,"",'Input Sheet'!B19) | B22: =IFERROR(VLOOKUP(A22,$A23:A$1005,1,FALSE)=0,1) -> FALSE | C22: =SUMIF('Input Sheet'!B$3:B$1000,A22,'Input Sheet'!C$3:C$1000) -> 0 | D22: =SUMIF('Input Sheet'!B$3:B$1000,A22,'Input Sheet'!D$3:D$1000) -> 0 | E22: =IFERROR(RANK(K22,K$6:K$1004,1),"") | F22: =IFERROR(RANK(L22,L$6:L$1004,1),"") | G22: =IFERROR(RANK(L22,L$6:L$1004,0),"") | H22: =IF($B22=1,$A22,"") | I22: =IF($B22=1,$C22,"") | J22: =IF($B22=1,$D22,"") | K22: =IF($B22=1,$C22/$D22+RAND()/1000,"") | L22: =IF($B22=1,$D22-$C22+RAND()/1000,"") | M22: =IF(SUMIFS('Input Sheet'!$F$3:$F$1001,'Input Sheet'!$B$3:$B$1001,$H22,'Input Sheet'!$E$3:$E$1001,M$4)=0,"",SUMIFS('Input Sheet'!$F$3:$F$1001,'Input Sheet'!$B$3:$B$1001,$H22,'Input Sheet'!$E$3:$E$1001,M$4)) | N22: =IF(SUMIFS('Input Sheet'!$F$3:$F$1001,'Input Sheet'!$B$3:$B$1001,$H22,'Input Sheet'!$E$3:$E$1001,N$4)=0,"",SUMIFS('Input Sheet'!$F$3:$F$1001,'Input Sheet'!$B$3:$B$1001,$H22,'Input Sheet'!$E$3:$E$1001,N$4)) | O22: =IF(SUMIFS('Input Sheet'!$F$3:$F$1001,'Input Sheet'!$B$3:$B$1001,$H22,'Input Sheet'!$E$3:$E$1001,O$4)=0,"",SUMIFS('Input Sheet'!$F$3:$F$1001,'Input Sheet'!$B$3:$B$1001,$H22,'Input Sheet'!$E$3:$E$1001,O$4)) | P22: =IF(SUMIFS('Input Sheet'!$F$3:$F$1001,'Input Sheet'!$B$3:$B$1001,$H22,'Input Sheet'!$E$3:$E$1001,P$4)=0,"",SUMIFS('Input Sheet'!$F$3:$F$1001,'Input Sheet'!$B$3:$B$1001,$H22,'Input Sheet'!$E$3:$E$1001,P$4)) | Q22: =IF(SUMIFS('Input Sheet'!$F$3:$F$1001,'Input Sheet'!$B$3:$B$1001,$H22,'Input Sheet'!$E$3:$E$1001,Q$4)=0,"",SUMIFS('Input Sheet'!$F$3:$F$1001,'Input Sheet'!$B$3:$B$1001,$H22,'Input Sheet'!$E$3:$E$1001,Q$4)) | R22: =IF(SUMIFS('Input Sheet'!$F$3:$F$1001,'Input Sheet'!$B$3:$B$1001,$H22,'Input Sheet'!$E$3:$E$1001,R$4)=0,"",SUMIFS('Input Sheet'!$F$3:$F$1001,'Input Sheet'!$B$3:$B$1001,$H22,'Input Sheet'!$E$3:$E$1001,R$4)) | S22: =IF(SUMIFS('Input Sheet'!$F$3:$F$1001,'Input Sheet'!$B$3:$B$1001,$H22,'Input Sheet'!$E$3:$E$1001,S$4)=0,"",SUMIFS('Input Sheet'!$F$3:$F$1001,'Input Sheet'!$B$3:$B$1001,$H22,'Input Sheet'!$E$3:$E$1001,S$4)) | T22: 17
A23: =IF('Input Sheet'!B20=0,"",'Input Sheet'!B20) | B23: =IFERROR(VLOOKUP(A23,$A24:A$1005,1,FALSE)=0,1) -> FALSE | C23: =SUMIF('Input Sheet'!B$3:B$1000,A23,'Input Sheet'!C$3:C$1000) -> 0 | D23: =SUMIF('Input Sheet'!B$3:B$1000,A23,'Input Sheet'!D$3:D$1000) -> 0 | E23: =IFERROR(RANK(K23,K$6:K$1004,1),"") | F23: =IFERROR(RANK(L23,L$6:L$1004,1),"") | G23: =IFERROR(RANK(L23,L$6:L$1004,0),"") | H23: =IF($B23=1,$A23,"") | I23: =IF($B23=1,$C23,"") | J23: =IF($B23=1,$D23,"") | K23: =IF($B23=1,$C23/$D23+RAND()/1000,"") | L23: =IF($B23=1,$D23-$C23+RAND()/1000,"") | M23: =IF(SUMIFS('Input Sheet'!$F$3:$F$1001,'Input Sheet'!$B$3:$B$1001,$H23,'Input Sheet'!$E$3:$E$1001,M$4)=0,"",SUMIFS('Input Sheet'!$F$3:$F$1001,'Input Sheet'!$B$3:$B$1001,$H23,'Input Sheet'!$E$3:$E$1001,M$4)) | N23: =IF(SUMIFS('Input Sheet'!$F$3:$F$1001,'Input Sheet'!$B$3:$B$1001,$H23,'Input Sheet'!$E$3:$E$1001,N$4)=0,"",SUMIFS('Input Sheet'!$F$3:$F$1001,'Input Sheet'!$B$3:$B$1001,$H23,'Input Sheet'!$E$3:$E$1001,N$4)) | O23: =IF(SUMIFS('Input Sheet'!$F$3:$F$1001,'Input Sheet'!$B$3:$B$1001,$H23,'Input Sheet'!$E$3:$E$1001,O$4)=0,"",SUMIFS('Input Sheet'!$F$3:$F$1001,'Input Sheet'!$B$3:$B$1001,$H23,'Input Sheet'!$E$3:$E$1001,O$4)) | P23: =IF(SUMIFS('Input Sheet'!$F$3:$F$1001,'Input Sheet'!$B$3:$B$1001,$H23,'Input Sheet'!$E$3:$E$1001,P$4)=0,"",SUMIFS('Input Sheet'!$F$3:$F$1001,'Input Sheet'!$B$3:$B$1001,$H23,'Input Sheet'!$E$3:$E$1001,P$4)) | Q23: =IF(SUMIFS('Input Sheet'!$F$3:$F$1001,'Input Sheet'!$B$3:$B$1001,$H23,'Input Sheet'!$E$3:$E$1001,Q$4)=0,"",SUMIFS('Input Sheet'!$F$3:$F$1001,'Input Sheet'!$B$3:$B$1001,$H23,'Input Sheet'!$E$3:$E$1001,Q$4)) | R23: =IF(SUMIFS('Input Sheet'!$F$3:$F$1001,'Input Sheet'!$B$3:$B$1001,$H23,'Input Sheet'!$E$3:$E$1001,R$4)=0,"",SUMIFS('Input Sheet'!$F$3:$F$1001,'Input Sheet'!$B$3:$B$1001,$H23,'Input Sheet'!$E$3:$E$1001,R$4)) | S23: =IF(SUMIFS('Input Sheet'!$F$3:$F$1001,'Input Sheet'!$B$3:$B$1001,$H23,'Input Sheet'!$E$3:$E$1001,S$4)=0,"",SUMIFS('Input Sheet'!$F$3:$F$1001,'Input Sheet'!$B$3:$B$1001,$H23,'Input Sheet'!$E$3:$E$1001,S$4)) | T23: 18
A24: =IF('Input Sheet'!B21=0,"",'Input Sheet'!B21) | B24: =IFERROR(VLOOKUP(A24,$A25:A$1005,1,FALSE)=0,1) -> FALSE | C24: =SUMIF('Input Sheet'!B$3:B$1000,A24,'Input Sheet'!C$3:C$1000) -> 0 | D24: =SUMIF('Input Sheet'!B$3:B$1000,A24,'Input Sheet'!D$3:D$1000) -> 0 | E24: =IFERROR(RANK(K24,K$6:K$1004,1),"") | F24: =IFERROR(RANK(L24,L$6:L$1004,1),"") | G24: =IFERROR(RANK(L24,L$6:L$1004,0),"") | H24: =IF($B24=1,$A24,"") | I24: =IF($B24=1,$C24,"") | J24: =IF($B24=1,$D24,"") | K24: =IF($B24=1,$C24/$D24+RAND()/1000,"") | L24: =IF($B24=1,$D24-$C24+RAND()/1000,"") | M24: =IF(SUMIFS('Input Sheet'!$F$3:$F$1001,'Input Sheet'!$B$3:$B$1001,$H24,'Input Sheet'!$E$3:$E$1001,M$4)=0,"",SUMIFS('Input Sheet'!$F$3:$F$1001,'Input Sheet'!$B$3:$B$1001,$H24,'Input Sheet'!$E$3:$E$1001,M$4)) | N24: =IF(SUMIFS('Input Sheet'!$F$3:$F$1001,'Input Sheet'!$B$3:$B$1001,$H24,'Input Sheet'!$E$3:$E$1001,N$4)=0,"",SUMIFS('Input Sheet'!$F$3:$F$1001,'Input Sheet'!$B$3:$B$1001,$H24,'Input Sheet'!$E$3:$E$1001,N$4)) | O24: =IF(SUMIFS('Input Sheet'!$F$3:$F$1001,'Input Sheet'!$B$3:$B$1001,$H24,'Input Sheet'!$E$3:$E$1001,O$4)=0,"",SUMIFS('Input Sheet'!$F$3:$F$1001,'Input Sheet'!$B$3:$B$1001,$H24,'Input Sheet'!$E$3:$E$1001,O$4)) | P24: =IF(SUMIFS('Input Sheet'!$F$3:$F$1001,'Input Sheet'!$B$3:$B$1001,$H24,'Input Sheet'!$E$3:$E$1001,P$4)=0,"",SUMIFS('Input Sheet'!$F$3:$F$1001,'Input Sheet'!$B$3:$B$1001,$H24,'Input Sheet'!$E$3:$E$1001,P$4)) | Q24: =IF(SUMIFS('Input Sheet'!$F$3:$F$1001,'Input Sheet'!$B$3:$B$1001,$H24,'Input Sheet'!$E$3:$E$1001,Q$4)=0,"",SUMIFS('Input Sheet'!$F$3:$F$1001,'Input Sheet'!$B$3:$B$1001,$H24,'Input Sheet'!$E$3:$E$1001,Q$4)) | R24: =IF(SUMIFS('Input Sheet'!$F$3:$F$1001,'Input Sheet'!$B$3:$B$1001,$H24,'Input Sheet'!$E$3:$E$1001,R$4)=0,"",SUMIFS('Input Sheet'!$F$3:$F$1001,'Input Sheet'!$B$3:$B$1001,$H24,'Input Sheet'!$E$3:$E$1001,R$4)) | S24: =IF(SUMIFS('Input Sheet'!$F$3:$F$1001,'Input Sheet'!$B$3:$B$1001,$H24,'Input Sheet'!$E$3:$E$1001,S$4)=0,"",SUMIFS('Input Sheet'!$F$3:$F$1001,'Input Sheet'!$B$3:$B$1001,$H24,'Input Sheet'!$E$3:$E$1001,S$4)) | T24: 19
... A1005: =IF('Input Sheet'!B1002=0,"",'Input Sheet'!B1002) | B1005: =IFERROR(VLOOKUP(A1005,$A1006:A$1005,1,FALSE)=0,1) -> FALSE | C1005: =SUMIF('Input Sheet'!B$3:B$1000,A1005,'Input Sheet'!C$3:C$1000) -> 0 | D1005: =SUMIF('Input Sheet'!B$3:B$1000,A1005,'Input Sheet'!D$3:D$1000) -> 0 | E1005: =IFERROR(RANK(K1005,K$6:K$1004,1),"") | F1005: =IFERROR(RANK(L1005,L$6:L$1004,1),"") | G1005: =IFERROR(RANK(L1005,L$6:L$1004,0),"") | H1005: =IF($B1005=1,$A1005,"") | I1005: =IF($B1005=1,$C1005,"") | J1005: =IF($B1005=1,$D1005,"") | K1005: =IF($B1005=1,$C1005/$D1005+RAND()/1000,"") | L1005: =IF($B1005=1,$D1005-$C1005+RAND()/1000,"") | M1005: =IF(SUMIFS('Input Sheet'!$F$3:$F$1001,'Input Sheet'!$B$3:$B$1001,$H1005,'Input Sheet'!$E$3:$E$1001,M$4)=0,"",SUMIFS('Input Sheet'!$F$3:$F$1001,'Input Sheet'!$B$3:$B$1001,$H1005,'Input Sheet'!$E$3:$E$1001,M$4)) | N1005: =IF(SUMIFS('Input Sheet'!$F$3:$F$1001,'Input Sheet'!$B$3:$B$1001,$H1005,'Input Sheet'!$E$3:$E$1001,N$4)=0,"",SUMIFS('Input Sheet'!$F$3:$F$1001,'Input Sheet'!$B$3:$B$1001,$H1005,'Input Sheet'!$E$3:$E$1001,N$4)) | O1005: =IF(SUMIFS('Input Sheet'!$F$3:$F$1001,'Input Sheet'!$B$3:$B$1001,$H1005,'Input Sheet'!$E$3:$E$1001,O$4)=0,"",SUMIFS('Input Sheet'!$F$3:$F$1001,'Input Sheet'!$B$3:$B$1001,$H1005,'Input Sheet'!$E$3:$E$1001,O$4)) | P1005: =IF(SUMIFS('Input Sheet'!$F$3:$F$1001,'Input Sheet'!$B$3:$B$1001,$H1005,'Input Sheet'!$E$3:$E$1001,P$4)=0,"",SUMIFS('Input Sheet'!$F$3:$F$1001,'Input Sheet'!$B$3:$B$1001,$H1005,'Input Sheet'!$E$3:$E$1001,P$4)) | Q1005: =IF(SUMIFS('Input Sheet'!$F$3:$F$1001,'Input Sheet'!$B$3:$B$1001,$H1005,'Input Sheet'!$E$3:$E$1001,Q$4)=0,"",SUMIFS('Input Sheet'!$F$3:$F$1001,'Input Sheet'!$B$3:$B$1001,$H1005,'Input Sheet'!$E$3:$E$1001,Q$4)) | R1005: =IF(SUMIFS('Input Sheet'!$F$3:$F$1001,'Input Sheet'!$B$3:$B$1001,$H1005,'Input Sheet'!$E$3:$E$1001,R$4)=0,"",SUMIFS('Input Sheet'!$F$3:$F$1001,'Input Sheet'!$B$3:$B$1001,$H1005,'Input Sheet'!$E$3:$E$1001,R$4)) | S1005: =IF(SUMIFS('Input Sheet'!$F$3:$F$1001,'Input Sheet'!$B$3:$B$1001,$H1005,'Input Sheet'!$E$3:$E$1001,S$4)=0,"",SUMIFS('Input Sheet'!$F$3:$F$1001,'Input Sheet'!$B$3:$B$1001,$H1005,'Input Sheet'!$E$3:$E$1001,S$4)) | T1005: 1000

Sheet Graph Output
L1: THIS IS ALL DONE AUTOMATICALLY, DO NOT EDIT THIS PAGE (EXCEPT PINK INSTRUCTION)
A2: Title No | B2: Section/ Taxonomy Title | C2: Marks Scored | D2: Marks Available | E2: Score | F2: Click Graph, and drag down selection box to include all of the line items ----> | G2: Section/ Taxonomy Title | H2: Marks Scored | I2: Marks Available | J2: Marks Lost | K2: Click Graph, and drag down selection box to include all of the line items ----> | L2: Section/ Taxonomy Title | M2: =IFERROR(HLOOKUP(Calculation!M3,Calculation!$M$2:$S$4,3,FALSE),"") -> Concept | N2: =IFERROR(HLOOKUP(Calculation!N3,Calculation!$M$2:$S$4,3,FALSE),"") -> Application | O2: =IFERROR(HLOOKUP(Calculation!O3,Calculation!$M$2:$S$4,3,FALSE),"") -> Misread Direction | P2: =IFERROR(HLOOKUP(Calculation!P3,Calculation!$M$2:$S$4,3,FALSE),"") -> Careless | Q2: =IFERROR(HLOOKUP(Calculation!Q3,Calculation!$M$2:$S$4,3,FALSE),"") -> Test Procedure | R2: =IFERROR(HLOOKUP(Calculation!R3,Calculation!$M$2:$S$4,3,FALSE),"") -> Omission | S2: Click Graph, and drag down selection box to include all of the line items ----> | T2: Error Type | U2: Total Marks Lost
A3: =IF(Calculation!T6<=Calculation!$H$4,Calculation!T6,"") -> 1 | B3: =VLOOKUP(A3,Calculation!$E$6:$J$1004,4,FALSE) -> Algebraic Expressions | C3: =VLOOKUP(A3,Calculation!$E$6:$J$1004,5,FALSE) -> 0 | D3: =VLOOKUP(A3,Calculation!$E$6:$J$1004,6,FALSE) -> 8 | E3: =IF(C3=0,0.0001,IF($A3="","",$C3/$D3)) -> 0.0001 | G3: =VLOOKUP(A3,Calculation!$F$6:$J$1004,3,FALSE) -> Trigonometry | H3: =VLOOKUP(A3,Calculation!$F$6:$J$1004,4,FALSE) -> 4 | I3: =VLOOKUP(A3,Calculation!$F$6:$J$1004,5,FALSE) -> 5 | J3: =IF($A3="","",$I3-$H3) -> 1 | L3: =VLOOKUP(A3,Calculation!$G$6:$S$1004,2,FALSE) -> Exponents | M3: =IFERROR(VLOOKUP($L3,Calculation!$H$6:$S$1005,HLOOKUP(M$2,Calculation!$M$4:$S$5,2,FALSE)+5,FALSE),"") | N3: =IFERROR(VLOOKUP($L3,Calculation!$H$6:$S$1005,HLOOKUP(N$2,Calculation!$M$4:$S$5,2,FALSE)+5,FALSE),"") | O3: =IFERROR(VLOOKUP($L3,Calculation!$H$6:$S$1005,HLOOKUP(O$2,Calculation!$M$4:$S$5,2,FALSE)+5,FALSE),"") -> 8 | P3: =IFERROR(VLOOKUP($L3,Calculation!$H$6:$S$1005,HLOOKUP(P$2,Calculation!$M$4:$S$5,2,FALSE)+5,FALSE),"") -> 6 | Q3: =IFERROR(VLOOKUP($L3,Calculation!$H$6:$S$1005,HLOOKUP(Q$2,Calculation!$M$4:$S$5,2,FALSE)+5,FALSE),"") -> 1 | R3: =IFERROR(VLOOKUP($L3,Calculation!$H$6:$S$1005,HLOOKUP(R$2,Calculation!$M$4:$S$5,2,FALSE)+5,FALSE),"") -> 1 | T3: =IFERROR(HLOOKUP(Calculation!M3,Calculation!$M$2:$S$4,3,FALSE),"") -> Concept | U3: =IFERROR(VLOOKUP(T3,Calculation!$U$6:$V$11,2,FALSE),"") -> 12
A4: =IF(Calculation!T7<=Calculation!$H$4,Calculation!T7,"") -> 2 | B4: =VLOOKUP(A4,Calculation!$E$6:$J$1004,4,FALSE) -> Exponents | C4: =VLOOKUP(A4,Calculation!$E$6:$J$1004,5,FALSE) -> 0 | D4: =VLOOKUP(A4,Calculation!$E$6:$J$1004,6,FALSE) -> 16 | E4: =IF(C4=0,0.0001,IF($A4="","",$C4/$D4)) -> 0.0001 | G4: =VLOOKUP(A4,Calculation!$F$6:$J$1004,3,FALSE) -> Functions | H4: =VLOOKUP(A4,Calculation!$F$6:$J$1004,4,FALSE) -> 6 | I4: =VLOOKUP(A4,Calculation!$F$6:$J$1004,5,FALSE) -> 8 | J4: =IF($A4="","",$I4-$H4) -> 2 | L4: =VLOOKUP(A4,Calculation!$G$6:$S$1004,2,FALSE) -> Number Patterns | M4: =IFERROR(VLOOKUP($L4,Calculation!$H$6:$S$1005,HLOOKUP(M$2,Calculation!$M$4:$S$5,2,FALSE)+5,FALSE),"") -> 10 | N4: =IFERROR(VLOOKUP($L4,Calculation!$H$6:$S$1005,HLOOKUP(N$2,Calculation!$M$4:$S$5,2,FALSE)+5,FALSE),"") -> 2 | O4: =IFERROR(VLOOKUP($L4,Calculation!$H$6:$S$1005,HLOOKUP(O$2,Calculation!$M$4:$S$5,2,FALSE)+5,FALSE),"") | P4: =IFERROR(VLOOKUP($L4,Calculation!$H$6:$S$1005,HLOOKUP(P$2,Calculation!$M$4:$S$5,2,FALSE)+5,FALSE),"") | Q4: =IFERROR(VLOOKUP($L4,Calculation!$H$6:$S$1005,HLOOKUP(Q$2,Calculation!$M$4:$S$5,2,FALSE)+5,FALSE),"") | R4: =IFERROR(VLOOKUP($L4,Calculation!$H$6:$S$1005,HLOOKUP(R$2,Calculation!$M$4:$S$5,2,FALSE)+5,FALSE),"") | T4: =IFERROR(HLOOKUP(Calculation!N3,Calculation!$M$2:$S$4,3,FALSE),"") -> Application | U4: =IFERROR(VLOOKUP(T4,Calculation!$U$6:$V$11,2,FALSE),"") -> 10
A5: =IF(Calculation!T8<=Calculation!$H$4,Calculation!T8,"") -> 3 | B5: =VLOOKUP(A5,Calculation!$E$6:$J$1004,4,FALSE) -> Number Patterns | C5: =VLOOKUP(A5,Calculation!$E$6:$J$1004,5,FALSE) -> 6 | D5: =VLOOKUP(A5,Calculation!$E$6:$J$1004,6,FALSE) -> 18 | E5: =IF(C5=0,0.0001,IF($A5="","",$C5/$D5)) -> 0.33333333 | G5: =VLOOKUP(A5,Calculation!$F$6:$J$1004,3,FALSE) -> Algebraic Expressions | H5: =VLOOKUP(A5,Calculation!$F$6:$J$1004,4,FALSE) -> 0 | I5: =VLOOKUP(A5,Calculation!$F$6:$J$1004,5,FALSE) -> 8 | J5: =IF($A5="","",$I5-$H5) -> 8 | L5: =VLOOKUP(A5,Calculation!$G$6:$S$1004,2,FALSE) -> Algebraic Expressions | M5: =IFERROR(VLOOKUP($L5,Calculation!$H$6:$S$1005,HLOOKUP(M$2,Calculation!$M$4:$S$5,2,FALSE)+5,FALSE),"") | N5: =IFERROR(VLOOKUP($L5,Calculation!$H$6:$S$1005,HLOOKUP(N$2,Calculation!$M$4:$S$5,2,FALSE)+5,FALSE),"") -> 8 | O5: =IFERROR(VLOOKUP($L5,Calculation!$H$6:$S$1005,HLOOKUP(O$2,Calculation!$M$4:$S$5,2,FALSE)+5,FALSE),"") | P5: =IFERROR(VLOOKUP($L5,Calculation!$H$6:$S$1005,HLOOKUP(P$2,Calculation!$M$4:$S$5,2,FALSE)+5,FALSE),"") | Q5: =IFERROR(VLOOKUP($L5,Calculation!$H$6:$S$1005,HLOOKUP(Q$2,Calculation!$M$4:$S$5,2,FALSE)+5,FALSE),"") | R5: =IFERROR(VLOOKUP($L5,Calculation!$H$6:$S$1005,HLOOKUP(R$2,Calculation!$M$4:$S$5,2,FALSE)+5,FALSE),"") | T5: =IFERROR(HLOOKUP(Calculation!O3,Calculation!$M$2:$S$4,3,FALSE),"") -> Misread Direction | U5: =IFERROR(VLOOKUP(T5,Calculation!$U$6:$V$11,2,FALSE),"") -> 8
A6: =IF(Calculation!T9<=Calculation!$H$4,Calculation!T9,"") -> 4 | B6: =VLOOKUP(A6,Calculation!$E$6:$J$1004,4,FALSE) -> Functions | C6: =VLOOKUP(A6,Calculation!$E$6:$J$1004,5,FALSE) -> 6 | D6: =VLOOKUP(A6,Calculation!$E$6:$J$1004,6,FALSE) -> 8 | E6: =IF(C6=0,0.0001,IF($A6="","",$C6/$D6)) -> 0.75 | G6: =VLOOKUP(A6,Calculation!$F$6:$J$1004,3,FALSE) -> Number Patterns | H6: =VLOOKUP(A6,Calculation!$F$6:$J$1004,4,FALSE) -> 6 | I6: =VLOOKUP(A6,Calculation!$F$6:$J$1004,5,FALSE) -> 18 | J6: =IF($A6="","",$I6-$H6) -> 12 | L6: =VLOOKUP(A6,Calculation!$G$6:$S$1004,2,FALSE) -> Functions | M6: =IFERROR(VLOOKUP($L6,Calculation!$H$6:$S$1005,HLOOKUP(M$2,Calculation!$M$4:$S$5,2,FALSE)+5,FALSE),"") -> 2 | N6: =IFERROR(VLOOKUP($L6,Calculation!$H$6:$S$1005,HLOOKUP(N$2,Calculation!$M$4:$S$5,2,FALSE)+5,FALSE),"") | O6: =IFERROR(VLOOKUP($L6,Calculation!$H$6:$S$1005,HLOOKUP(O$2,Calculation!$M$4:$S$5,2,FALSE)+5,FALSE),"") | P6: =IFERROR(VLOOKUP($L6,Calculation!$H$6:$S$1005,HLOOKUP(P$2,Calculation!$M$4:$S$5,2,FALSE)+5,FALSE),"") | Q6: =IFERROR(VLOOKUP($L6,Calculation!$H$6:$S$1005,HLOOKUP(Q$2,Calculation!$M$4:$S$5,2,FALSE)+5,FALSE),"") | R6: =IFERROR(VLOOKUP($L6,Calculation!$H$6:$S$1005,HLOOKUP(R$2,Calculation!$M$4:$S$5,2,FALSE)+5,FALSE),"") | T6: =IFERROR(HLOOKUP(Calculation!P3,Calculation!$M$2:$S$4,3,FALSE),"") -> Careless | U6: =IFERROR(VLOOKUP(T6,Calculation!$U$6:$V$11,2,FALSE),"") -> 6
A7: =IF(Calculation!T10<=Calculation!$H$4,Calculation!T10,"") -> 5 | B7: =VLOOKUP(A7,Calculation!$E$6:$J$1004,4,FALSE) -> Trigonometry | C7: =VLOOKUP(A7,Calculation!$E$6:$J$1004,5,FALSE) -> 4 | D7: =VLOOKUP(A7,Calculation!$E$6:$J$1004,6,FALSE) -> 5 | E7: =IF(C7=0,0.0001,IF($A7="","",$C7/$D7)) -> 0.8 | G7: =VLOOKUP(A7,Calculation!$F$6:$J$1004,3,FALSE) -> Exponents | H7: =VLOOKUP(A7,Calculation!$F$6:$J$1004,4,FALSE) -> 0 | I7: =VLOOKUP(A7,Calculation!$F$6:$J$1004,5,FALSE) -> 16 | J7: =IF($A7="","",$I7-$H7) -> 16 | L7: =VLOOKUP(A7,Calculation!$G$6:$S$1004,2,FALSE) -> Trigonometry | M7: =IFERROR(VLOOKUP($L7,Calculation!$H$6:$S$1005,HLOOKUP(M$2,Calculation!$M$4:$S$5,2,FALSE)+5,FALSE),"") | N7: =IFERROR(VLOOKUP($L7,Calculation!$H$6:$S$1005,HLOOKUP(N$2,Calculation!$M$4:$S$5,2,FALSE)+5,FALSE),"") | O7: =IFERROR(VLOOKUP($L7,Calculation!$H$6:$S$1005,HLOOKUP(O$2,Calculation!$M$4:$S$5,2,FALSE)+5,FALSE),"") | P7: =IFERROR(VLOOKUP($L7,Calculation!$H$6:$S$1005,HLOOKUP(P$2,Calculation!$M$4:$S$5,2,FALSE)+5,FALSE),"") | Q7: =IFERROR(VLOOKUP($L7,Calculation!$H$6:$S$1005,HLOOKUP(Q$2,Calculation!$M$4:$S$5,2,FALSE)+5,FALSE),"") -> 1 | R7: =IFERROR(VLOOKUP($L7,Calculation!$H$6:$S$1005,HLOOKUP(R$2,Calculation!$M$4:$S$5,2,FALSE)+5,FALSE),"") | T7: =IFERROR(HLOOKUP(Calculation!Q3,Calculation!$M$2:$S$4,3,FALSE),"") -> Test Procedure | U7: =IFERROR(VLOOKUP(T7,Calculation!$U$6:$V$11,2,FALSE),"") -> 2
A8: =IF(Calculation!T11<=Calculation!$H$4,Calculation!T11,"") | B8: =VLOOKUP(A8,Calculation!$E$6:$J$1004,4,FALSE) | C8: =VLOOKUP(A8,Calculation!$E$6:$J$1004,5,FALSE) | D8: =VLOOKUP(A8,Calculation!$E$6:$J$1004,6,FALSE) | E8: =IF(C8=0,0.0001,IF($A8="","",$C8/$D8)) | G8: =VLOOKUP(A8,Calculation!$F$6:$J$1004,3,FALSE) | H8: =VLOOKUP(A8,Calculation!$F$6:$J$1004,4,FALSE) | I8: =VLOOKUP(A8,Calculation!$F$6:$J$1004,5,FALSE) | J8: =IF($A8="","",$I8-$H8) | L8: =VLOOKUP(A8,Calculation!$G$6:$S$1004,2,FALSE) | M8: =IFERROR(VLOOKUP($L8,Calculation!$H$6:$S$1005,HLOOKUP(M$2,Calculation!$M$4:$S$5,2,FALSE)+5,FALSE),"") | N8: =IFERROR(VLOOKUP($L8,Calculation!$H$6:$S$1005,HLOOKUP(N$2,Calculation!$M$4:$S$5,2,FALSE)+5,FALSE),"") | O8: =IFERROR(VLOOKUP($L8,Calculation!$H$6:$S$1005,HLOOKUP(O$2,Calculation!$M$4:$S$5,2,FALSE)+5,FALSE),"") | P8: =IFERROR(VLOOKUP($L8,Calculation!$H$6:$S$1005,HLOOKUP(P$2,Calculation!$M$4:$S$5,2,FALSE)+5,FALSE),"") | Q8: =IFERROR(VLOOKUP($L8,Calculation!$H$6:$S$1005,HLOOKUP(Q$2,Calculation!$M$4:$S$5,2,FALSE)+5,FALSE),"") | R8: =IFERROR(VLOOKUP($L8,Calculation!$H$6:$S$1005,HLOOKUP(R$2,Calculation!$M$4:$S$5,2,FALSE)+5,FALSE),"") | T8: =IFERROR(HLOOKUP(Calculation!R3,Calculation!$M$2:$S$4,3,FALSE),"") -> Omission | U8: =IFERROR(VLOOKUP(T8,Calculation!$U$6:$V$11,2,FALSE),"") -> 1
A9: =IF(Calculation!T12<=Calculation!$H$4,Calculation!T12,"") | B9: =VLOOKUP(A9,Calculation!$E$6:$J$1004,4,FALSE) | C9: =VLOOKUP(A9,Calculation!$E$6:$J$1004,5,FALSE) | D9: =VLOOKUP(A9,Calculation!$E$6:$J$1004,6,FALSE) | E9: =IF(C9=0,0.0001,IF($A9="","",$C9/$D9)) | G9: =VLOOKUP(A9,Calculation!$F$6:$J$1004,3,FALSE) | H9: =VLOOKUP(A9,Calculation!$F$6:$J$1004,4,FALSE) | I9: =VLOOKUP(A9,Calculation!$F$6:$J$1004,5,FALSE) | J9: =IF($A9="","",$I9-$H9) | L9: =VLOOKUP(A9,Calculation!$G$6:$S$1004,2,FALSE) | M9: =IFERROR(VLOOKUP($L9,Calculation!$H$6:$S$1005,HLOOKUP(M$2,Calculation!$M$4:$S$5,2,FALSE)+5,FALSE),"") | N9: =IFERROR(VLOOKUP($L9,Calculation!$H$6:$S$1005,HLOOKUP(N$2,Calculation!$M$4:$S$5,2,FALSE)+5,FALSE),"") | O9: =IFERROR(VLOOKUP($L9,Calculation!$H$6:$S$1005,HLOOKUP(O$2,Calculation!$M$4:$S$5,2,FALSE)+5,FALSE),"") | P9: =IFERROR(VLOOKUP($L9,Calculation!$H$6:$S$1005,HLOOKUP(P$2,Calculation!$M$4:$S$5,2,FALSE)+5,FALSE),"") | Q9: =IFERROR(VLOOKUP($L9,Calculation!$H$6:$S$1005,HLOOKUP(Q$2,Calculation!$M$4:$S$5,2,FALSE)+5,FALSE),"") | R9: =IFERROR(VLOOKUP($L9,Calculation!$H$6:$S$1005,HLOOKUP(R$2,Calculation!$M$4:$S$5,2,FALSE)+5,FALSE),"") | U9: =IFERROR(VLOOKUP(T9,Calculation!$U$6:$V$11,2,FALSE),"")
A10: =IF(Calculation!T13<=Calculation!$H$4,Calculation!T13,"") | B10: =VLOOKUP(A10,Calculation!$E$6:$J$1004,4,FALSE) | C10: =VLOOKUP(A10,Calculation!$E$6:$J$1004,5,FALSE) | D10: =VLOOKUP(A10,Calculation!$E$6:$J$1004,6,FALSE) | E10: =IF(C10=0,0.0001,IF($A10="","",$C10/$D10)) | G10: =VLOOKUP(A10,Calculation!$F$6:$J$1004,3,FALSE) | H10: =VLOOKUP(A10,Calculation!$F$6:$J$1004,4,FALSE) | I10: =VLOOKUP(A10,Calculation!$F$6:$J$1004,5,FALSE) | J10: =IF($A10="","",$I10-$H10) | L10: =VLOOKUP(A10,Calculation!$G$6:$S$1004,2,FALSE) | M10: =IFERROR(VLOOKUP($L10,Calculation!$H$6:$S$1005,HLOOKUP(M$2,Calculation!$M$4:$S$5,2,FALSE)+5,FALSE),"") | N10: =IFERROR(VLOOKUP($L10,Calculation!$H$6:$S$1005,HLOOKUP(N$2,Calculation!$M$4:$S$5,2,FALSE)+5,FALSE),"") | O10: =IFERROR(VLOOKUP($L10,Calculation!$H$6:$S$1005,HLOOKUP(O$2,Calculation!$M$4:$S$5,2,FALSE)+5,FALSE),"") | P10: =IFERROR(VLOOKUP($L10,Calculation!$H$6:$S$1005,HLOOKUP(P$2,Calculation!$M$4:$S$5,2,FALSE)+5,FALSE),"") | Q10: =IFERROR(VLOOKUP($L10,Calculation!$H$6:$S$1005,HLOOKUP(Q$2,Calculation!$M$4:$S$5,2,FALSE)+5,FALSE),"") | R10: =IFERROR(VLOOKUP($L10,Calculation!$H$6:$S$1005,HLOOKUP(R$2,Calculation!$M$4:$S$5,2,FALSE)+5,FALSE),"") | U10: =IFERROR(VLOOKUP(T10,Calculation!$U$6:$V$11,2,FALSE),"")
A11: =IF(Calculation!T14<=Calculation!$H$4,Calculation!T14,"") | B11: =VLOOKUP(A11,Calculation!$E$6:$J$1004,4,FALSE) | C11: =VLOOKUP(A11,Calculation!$E$6:$J$1004,5,FALSE) | D11: =VLOOKUP(A11,Calculation!$E$6:$J$1004,6,FALSE) | E11: =IF(C11=0,0.0001,IF($A11="","",$C11/$D11)) | G11: =VLOOKUP(A11,Calculation!$F$6:$J$1004,3,FALSE) | H11: =VLOOKUP(A11,Calculation!$F$6:$J$1004,4,FALSE) | I11: =VLOOKUP(A11,Calculation!$F$6:$J$1004,5,FALSE) | J11: =IF($A11="","",$I11-$H11) | L11: =VLOOKUP(A11,Calculation!$G$6:$S$1004,2,FALSE) | M11: =IFERROR(VLOOKUP($L11,Calculation!$H$6:$S$1005,HLOOKUP(M$2,Calculation!$M$4:$S$5,2,FALSE)+5,FALSE),"") | N11: =IFERROR(VLOOKUP($L11,Calculation!$H$6:$S$1005,HLOOKUP(N$2,Calculation!$M$4:$S$5,2,FALSE)+5,FALSE),"") | O11: =IFERROR(VLOOKUP($L11,Calculation!$H$6:$S$1005,HLOOKUP(O$2,Calculation!$M$4:$S$5,2,FALSE)+5,FALSE),"") | P11: =IFERROR(VLOOKUP($L11,Calculation!$H$6:$S$1005,HLOOKUP(P$2,Calculation!$M$4:$S$5,2,FALSE)+5,FALSE),"") | Q11: =IFERROR(VLOOKUP($L11,Calculation!$H$6:$S$1005,HLOOKUP(Q$2,Calculation!$M$4:$S$5,2,FALSE)+5,FALSE),"") | R11: =IFERROR(VLOOKUP($L11,Calculation!$H$6:$S$1005,HLOOKUP(R$2,Calculation!$M$4:$S$5,2,FALSE)+5,FALSE),"") | U11: =IFERROR(VLOOKUP(T11,Calculation!$U$6:$V$11,2,FALSE),"")
